Workbook

Sheet DIFF
B1: MODIFIED
B2: 41961 | F2: ZHENAO TRIAL DIFFERENTIAL BREW PROTOCOL-NOV.2014
N3: Materials | P3: Seed | Q3: Start Up | R3: Main Ferm | T3: WORT | U3: TOTAL
N4: Water | Q4: =E20 -> 50 | U4: =Q4 -> 50 | V4: litres
E5: BREWING PARAMETERS | N5: TRS | Q5: 250 | R5: 14750 | U5: =SUM(Q5:R5) -> 15000 | V5: kg
J6: 稀释糖蜜 | K6: WORT | N6: Wort | Q6: =Q5/K9 -> 714.28571 | R6: =R5/K9 -> 42142.857 | U6: =SUM(Q6:R6) -> 42857.143 | V6: kg
B7: 目标蛋白含量 | D7: Target Protein | E7: 57-58 | F7: % | J7: Cane | K7: 0 | L7: % | N7: Ammonia [100%] | S7: 800 | U7: =SUM(Q7:S7) -> 800 | V7: kg
B8: 目标P 含量（P2O5) | D8: Target P2O5 | E8: 2.8-3.0 | F8: % | G8: 总氮 | H8: 总磷 | J8: Beet | K8: 100 | L8: % | N8: H3PO4[100%] | S8: 420 | U8: =SUM(Q8:S8) -> 420 | V8: kg
B9: 假定酵母对糖得率 | D9: Assumed Yield | E9: 1.55 | F9: kg Y30 / kg RS | G9: Totals kg | J9: Average Wort Concentration | K9: 0.35 | L9: kg RS / kg wort | N9: MAP / DAP | U9: =SUM(Q9:R9) -> 0 | V9: kg
B10: N 得率（不包含蜜中含氮） | D10: Assumed NAF | E10: 1.0- 1.05 | G10: NH3 [100%] | H10: H3PO4[75%] | J10: Wort Density | K10: 1.24 | L10: kg/litre | N10: (NH4)2SO4 | U10: =SUM(Q10:R10) -> 0 | V10: kg
B11: P 得率（不包含蜜中含磷） | D11: Assumed PAF | E11: 0.85 -0.95 | G11: 800 | H11: 420 | N11: MgSO4 | Q11: 25 | R11: 75 | U11: =SUM(Q11:T11) -> 100 | V11: kg
K12: FERMENTER | N12: ZnSO4 | Q12: 5 | U12: =SUM(Q12:T12) -> 5 | V12: kg
E13: START | F13: TOTAL | J13: Diameter | K13: 4 | L13: m 直径 | N13: CuSO4 | Q13: 50 | R13: 130 | U13: =SUM(Q13:R13) -> 180 | V13: g
D14: Assumed Yield on RS | F14: =1.55 -> 1.55 | G14: kg Y30 / kg FS | J14: Height | K14: 12 | L14: m 高 | N14: CoCl2 | U14: =SUM(Q14:R14) -> 0 | V14: g
B15: 底蜜 | D15: Wort | E15: =E16/$K$9 -> 714.28571 | F15: =F16/$K$9 -> 42857.143 | G15: kg | J15: Cross Section | K15: =PI()*K13^2/4 -> 12.566371 | L15: m2 底面积 | N15: Na2MoO4.2H20 | U15: =SUM(Q15:R15) -> 0 | V15: g
B16: 底糖 | D16: RS | E16: 250 | F16: 15000 | G16: kg | J16: Dish Volume | K16: 0 | L16: m3 盘体积 | N16: Thiamine (B1) | Q16: 1500 | U16: =SUM(Q16:R16) -> 1500 | V16: g
B17: 种子 | D17: Seed Y30 | E17: 4000 | G17: kg | J17: External Volumes | K17: 1 | L17: m3 盘体积 | N17: Ca.Pantothenate (B5) | Q17: 500 | R17: 2000 | U17: =SUM(Q17:S17) -> 2500 | V17: g
B18: 种子Y30 | D18: Assumed Seed Y30 conc | E18: 680 | G18: g Y30/lit | J18: Header & Air Tree Volume | K18: 0.5 | L18: m3 封头+烟筒体积 | N18: Pyridoxine (B6) | Q18: 800 | U18: =SUM(Q18:R18) -> 800 | V18: g
A19: 移种时间 | D19: Assumed time for seed transfer | E19: 20 | G19: minutes | J19: Nominal Ferm Volume | K19: =K14*K15+K16+K17-K18 -> 151.29645 | L19: m3 正常发酵体积 | N19: Biotin | Q19: 25 | U19: =SUM(Q19:R19) -> 25 | V19: g
A20: 底水 | D20: Additon initial Water | E20: 50 | G20: litres | J20: Anti-Foam Probes Level | K20: 1.5 | L20: m 消泡剂探针 | N20: H2SO4 | U20: =SUM(Q20:S20) -> 0 | V20: kg
A21: 初始体积 | D21: DCS Apparent Start Volume (hour 0) | E21: 57700 | G21: litres | J21: Hold-up Volume | K21: =K15*(K14-K20)+K16+K17 -> 132.94689 | L21: m3 滞留体积 | N21: Sod.Hypochlorite | U21: =SUM(Q21:R21) -> 0 | V21: litres
A22: 结束体积 | D22: DCS Apparent Final Volume | E22: 99800 | G22: litres | N22: Antifoam | U22: =SUM(Q22:R22) -> 0 | V22: litres
B23: 发酵时间 | D23: Fermentation Time | F23: 16 | G23: hours | K23: Actual kg or m3 at 1.000 Density | N23: NaCl | U23: =SUM(Q23:R23) -> 0 | V23: kg
B24: 成熟时间 | D24: Maturation Time | F24: 40 | G24: minutes | J24: Set Water | K24: 50000 | L24: kg | N24: Nitric acid | V24: litres
J25: Start Vol hr 0 | K25: 53000 | L25: kg
E26: Projected Cream Output | F26: =F16*E9+E17 -> 27250 | G26: kg Y30 | J26: Actual Final Vol | K26: 99800 | L26: kg | M26: Spin Pellet
H27: VOLUME m3 at 1.000 Density = Tonnes | M27: 28.5 | N27: % solids | S27: Ammonia：RS
S28: 0.057
D29: SET POINTS | J29: ALCOHOL | K29: Cell Concentration | M29: Total | N29: Growth | O29: Sugar Feed | R29: Ammonia Gas [100%] | T29: Phosphoric Acid [60%] | V29: Nutrient | W29: H2SO4 Balance pH
D30: Temp | E30: AIR | F30: pH | G30: Action for | I30: VOLUME | J30: v/v % | K30: Apparent | L30: Actual | M30: Fermenter | N30: Modulus | O30: Rate | P30: Total | Q30: Total | R30: Rate | S30: Total | T30: Rate | U30: Total
B31: BREW HOUR | D31: oC | E31: m3 / hour | G31: pH Control | H31: Actual | I31: % FILL | J31: GC Target | K31: g as-is/litre | L31: g Y30/litre | M31: Y30 kg | N31: G | O31: kg RS / hr | P31: RS kg | Q31: Wort kg | R31: kg NH3 / hr | S31: NH3 kg | T31: kg / hr | U31: H3PO4 kg
B32: Start Water | H32: 50 | K32: Inoculum > | M32: =E17 -> 4000 | N32: Set FS > | O32: 250 | R32: 0 | T32: 0 | V32: Start Nutrient
B33: start 0 | C33: 0 | D33: 30 | E33: 6300 | F33: 4.5 | H33: 57.7 | I33: =H33/$K$19*100 -> 38.137049 | J33: 0.2 | K33: =L33*30/$M$27 -> 84.210526 | L33: =M32/H32 -> 80
B34: 1 | C34: 0-1 | D34: 30 | E34: 6300 | F34: 4.5 | H34: =H33+Q34/1000 -> 58.271429 | I34: =H34/$K$19*100 -> 38.514737 | J34: 0.2 | K34: =L34*30/$M$27 -> 85.697346 | L34: =M34/H33 -> 81.412478 | M34: =M32+(O32+O34)*$E$9 -> 4697.5 | N34: =EXP(LN(M34/M32)/(80/60)) -> 1.1281195 | O34: 200 | P34: =O32+O34 -> 450 | Q34: =O34/$K$9 -> 571.42857 | R34: 21.869474 | S34: =R32+R34 -> 21.869474 | T34: 22 | U34: =T32+T34 -> 22
B35: =1+B34 -> 2 | C35: 1-2 | D35: 30 | E35: 6300 | F35: 4.8 | H35: =H34+Q35/1000 -> 59.357143 | I35: =H35/$K$19*100 -> 39.232344 | J35: 0.2 | K35: =L35*30/$M$27 -> 95.496832 | L35: =M35/H34 -> 90.721991 | M35: =M34+O35*$E$9 -> 5286.5 | N35: =M35/M34 -> 1.1253858 | O35: 380 | P35: =O35+P34 -> 830 | Q35: =O35/$K$9 -> 1085.7143 | R35: 26.821053 | S35: =R35+S34 -> 48.690526 | T35: 27 | U35: =T35+U34 -> 49
B36: =1+B35 -> 3 | C36: 2-3 | D36: 30 | E36: 7000 | F36: 5.1 | H36: =H35+Q36/1000 -> 60.785714 | I36: =H36/$K$19*100 -> 40.176564 | J36: 0.18 | K36: =L36*30/$M$27 -> 107.49382 | L36: =M36/H35 -> 102.11913 | M36: =M35+O36*$E$9 -> 6061.5 | N36: =M36/M35 -> 1.1465998 | O36: 500 | P36: =O36+P35 -> 1330 | Q36: =O36/$K$9 -> 1428.5714 | R36: 30 | S36: =R36+S35 -> 78.690526 | T36: 29 | U36: =T36+U35 -> 78
B37: =1+B36 -> 4 | C37: 3-4 | D37: 30 | E37: 7000 | F37: 5.2 | H37: =H36+Q37/1000 -> 62.51203 | I37: =H37/$K$19*100 -> 41.31758 | J37: 0.15 | K37: =L37*30/$M$27 -> 121.18544 | L37: =M37/H36 -> 115.12617 | M37: =M36+O37*$E$9 -> 6998.0263 | N37: =M37/M36 -> 1.1545041 | O37: 604.21053 | P37: =O37+P36 -> 1934.2105 | Q37: =O37/$K$9 -> 1726.3158 | R37: 35 | S37: =R37+S36 -> 113.69053 | T37: 32 | U37: =T37+U36 -> 110
B38: =1+B37 -> 5 | C38: 4-5 | D38: 30 | E38: 8400 | F38: 5.3 | H38: =H37+Q38/1000 -> 64.617293 | I38: =H38/$K$19*100 -> 42.709062 | J38: 0.13 | K38: =L38*30/$M$27 -> 137.07057 | L38: =M38/H37 -> 130.21704 | M38: =M37+O38*$E$9 -> 8140.1316 | N38: =M38/M37 -> 1.1632039 | O38: 736.84211 | P38: =O38+P37 -> 2671.0526 | Q38: =O38/$K$9 -> 2105.2632 | R38: 41 | S38: =R38+S37 -> 154.69053 | T38: 50 | U38: =T38+U37 -> 160
B39: =1+B38 -> 6 | C39: 5-6 | D39: 30 | E39: 9800 | F39: 5.4 | H39: =H38+Q39/1000 -> 67.097293 | I39: =H39/$K$19*100 -> 44.348228 | J39: 0.12 | K39: =L39*30/$M$27 -> 154.52164 | L39: =M39/H38 -> 146.79556 | M39: =M38+O39*$E$9 -> 9485.5316 | N39: =M39/M38 -> 1.1652799 | O39: 868 | P39: =O39+P38 -> 3539.0526 | Q39: =O39/$K$9 -> 2480 | R39: 49 | S39: =R39+S38 -> 203.69053 | T39: 52 | U39: =T39+U38 -> 212
B40: =1+B39 -> 7 | C40: 6-7 | D40: 30 | E40: 10500 | F40: 5.7 | H40: =H39+Q40/1000 -> 69.895188 | I40: =H40/$K$19*100 -> 46.197508 | J40: 0.1 | K40: =L40*30/$M$27 -> 172.62269 | L40: =M40/H39 -> 163.99156 | M40: =M39+O40*$E$9 -> 11003.389 | N40: =M40/M39 -> 1.1600182 | O40: 979.26316 | P40: =O40+P39 -> 4518.3158 | Q40: =O40/$K$9 -> 2797.8947 | R40: 54.838737 | S40: =R40+S39 -> 258.52926 | T40: 53 | U40: =T40+U39 -> 265 | V40: Second add.
...

Sheet 评价标准
A2: Lot No. | G2: Yield Y30 kg
A3: Strain
A4: Recipe
A5: time | B5: Air m3/h | C5: Volume | D5: pH | E5: Alcohol v/v% | F5: Cell gpl | G5: kg Y30 | H5: GM | I5: RS kg/h | J5: TFS | K5: Remark | L5: time | M5: Alcohol Profile | N5: GM profile
A6: 0 | L6: 0 | M6: 0.2
A7: 1 | L7: 1 | M7: 0.25 | N7: 1.2
A8: 2 | L8: 2 | M8: 0.23 | N8: 1.4
A9: 3 | L9: 3 | M9: 0.2 | N9: 1.35
A10: 4 | L10: 4 | M10: 0.18 | N10: 1.33
A11: 5 | L11: 5 | M11: 0.16 | N11: 1.3
A12: 6 | L12: 6 | M12: 0.14 | N12: 1.25
A13: 7 | L13: 7 | M13: 0.13 | N13: 1.21
A14: 8 | L14: 8 | M14: 0.12 | N14: 1.19
A15: 9 | L15: 9 | M15: 0.11 | N15: 1.17
A16: 10 | L16: 10 | M16: 0.1 | N16: 1.15
A17: 11 | L17: 11 | M17: 0.09 | N17: 1.13
A18: 12 | L18: 12 | M18: 0.08 | N18: 1.11
... A23: 17 | L23: 17 | M23: 0.005 | N23: 1
A24: 18
A25: 19
A26: 20
C28: 评价标准 | D28: 1. Yield 30 是单罐产量，越高越好。是评价操作好坏的最终标准。已经涂成黄色。
D29: 2. remark 是我个人对每个小时操作的评价。这个评价标准不好量化，比较复杂：有时侯上个小时操作出现错误，下个小时是在改正，有连贯性。
D30: 3. Alcohol 和GM 标准曲线。如果每个罐的Alcohol v/v %的趋势越和标准曲线符合，操作的就越好。同样也适合GM曲线。

Sheet 01
A2: Lot No. | B2: 2592 | D2: Seed No. | E2: 2580 | G2: Yield Y30 kg | H2: =G23-E4 -> 39453.593
A3: Strain | B3: 167 | D3: Seed m3 | E3: 7.7
A4: Recipe | B4: Diff | D4: Seed Y30 | E4: =43070*E3/69.1 -> 4799.4067
A5: time | B5: Air m3/h | C5: Volume | D5: pH | E5: Alcohol v/v% | F5: Cell gpl | G5: kg Y30 | H5: GM | I5: RS kg/h | J5: TFS | K5: Remark | L5: DeltaAlcohol | M5: DeltaGM | N5: AutoGM
A6: 0 | B6: 9470 | C6: 89.5 | D6: 4.96 | E6: 0.194 | F6: 59 | G6: =C6*F6 -> 5280.5 | J6: 300 | L6: =E6-评价标准!M6 -> -0.006
A7: 1 | B7: 9053 | C7: 89.6 | D7: 4.49 | E7: 0.226 | F7: 64 | G7: =C7*F7 -> 5734.4 | H7: 1.09 | I7: 389 | J7: =J6+I7 -> 689 | K7: 4 | L7: =E7-评价标准!M7 -> -0.024 | M7: =N7-评价标准!N7 -> -0.11404223 | N7: =G7/G6 -> 1.0859578
A8: 2 | B8: 9726 | C8: 91.1 | D8: 3.96 | E8: 0.203 | F8: 78 | G8: =C8*F8 -> 7105.8 | H8: 1.24 | I8: 560 | J8: =J7+I8 -> 1249 | K8: 5 | L8: =E8-评价标准!M8 -> -0.027 | M8: =N8-评价标准!N8 -> -0.16084682 | N8: =G8/G7 -> 1.2391532
A9: 3 | B9: 11577 | C9: 93.9 | D9: 4.19 | E9: 0.179 | F9: 96 | G9: =C9*F9 -> 9014.4 | H9: 1.27 | I9: 717 | J9: =J8+I9 -> 1966 | K9: 4.5 | L9: =E9-评价标准!M9 -> -0.021 | M9: =N9-评价标准!N9 -> -0.081402516 | N9: =G9/G8 -> 1.2685975
A10: 4 | B10: 14065 | C10: 96 | D10: 4.38 | E10: 0.13 | F10: 128 | G10: =C10*F10 -> 12288 | H10: 1.36 | I10: 939 | J10: =J9+I10 -> 2905 | K10: 2 | L10: =E10-评价标准!M10 -> -0.05 | M10: =N10-评价标准!N10 -> 0.03315229 | N10: =G10/G9 -> 1.3631523
A11: 5 | B11: 15897 | C11: 99.5 | D11: 4.82 | E11: 0.165 | F11: 155 | G11: =C11*F11 -> 15422.5 | H11: 1.26 | I11: 1208 | J11: =J10+I11 -> 4113 | K11: 4 | L11: =E11-评价标准!M11 -> 0.005 | M11: =N11-评价标准!N11 -> -0.044913737 | N11: =G11/G10 -> 1.2550863
A12: 6 | B12: 16911 | C12: 102.7 | D12: 5.05 | E12: 0.169 | F12: 177 | G12: =C12*F12 -> 18177.9 | H12: 1.18 | I12: 1202 | J12: =J11+I12 -> 5315 | K12: 4 | L12: =E12-评价标准!M12 -> 0.029 | M12: =N12-评价标准!N12 -> -0.071338953 | N12: =G12/G11 -> 1.178661
A13: 7 | B13: 18581 | C13: 105.4 | D13: 5.53 | E13: 0.139 | F13: 202 | G13: =C13*F13 -> 21290.8 | H13: 1.17 | I13: 1248 | J13: =J12+I13 -> 6563 | K13: 4 | L13: =E13-评价标准!M13 -> 0.009 | M13: =N13-评价标准!N13 -> -0.038753596 | N13: =G13/G12 -> 1.1712464
A14: 8 | B14: 19727 | C14: 112.1 | D14: 5.99 | E14: 0.111 | F14: 215 | G14: =C14*F14 -> 24101.5 | H14: 1.13 | I14: 1518 | J14: =J13+I14 -> 8081 | K14: 4.5 | L14: =E14-评价标准!M14 -> -0.009 | M14: =N14-评价标准!N14 -> -0.057985233 | N14: =G14/G13 -> 1.1320148
A15: 9 | B15: 19774 | C15: 116.1 | D15: 6.13 | E15: 0.092 | F15: 231 | G15: =C15*F15 -> 26819.1 | H15: 1.11 | I15: 1719 | J15: =J14+I15 -> 9800 | K15: 3 | L15: =E15-评价标准!M15 -> -0.018 | M15: =N15-评价标准!N15 -> -0.057243533 | N15: =G15/G14 -> 1.1127565
A16: 10 | B16: 18791 | C16: 120.4 | D16: 6.18 | E16: 0.105 | F16: 243 | G16: =C16*F16 -> 29257.2 | H16: 1.09 | I16: 1798 | J16: =J15+I16 -> 11598 | K16: 3.5 | L16: =E16-评价标准!M16 -> 0.005 | M16: =N16-评价标准!N16 -> -0.059090909 | N16: =G16/G15 -> 1.0909091
A17: 11 | B17: 19918 | C17: 124.8 | D17: 6.35 | E17: 0.119 | F17: 258 | G17: =C17*F17 -> 32198.4 | H17: 1.1 | I17: 1794 | J17: =J16+I17 -> 13392 | K17: 2 | L17: =E17-评价标准!M17 -> 0.029 | M17: =N17-评价标准!N17 -> -0.029470899 | N17: =G17/G16 -> 1.1005291
A18: 12 | B18: 20210 | C18: 129.4 | D18: 6.46 | E18: 0.081 | F18: 270 | G18: =C18*F18 -> 34938 | H18: 1.09 | I18: 1930 | J18: =J17+I18 -> 15322 | K18: 3.5 | L18: =E18-评价标准!M18 -> 0.001 | M18: =N18-评价标准!N18 -> -0.024915027 | N18: =G18/G17 -> 1.085085
... A22: 16 | B22: 14902 | C22: 147.3 | D22: 7.26 | E22: 0.013 | F22: 297 | G22: =C22*F22 -> 43748.1 | H22: 1.03 | I22: 1554 | J22: =J21+I22 -> 22455 | K22: 2.5 | L22: =E22-评价标准!M22 -> 0.003 | M22: =N22-评价标准!N22 -> 0.0057660167 | N22: =G22/G21 -> 1.025766
A23: 17 | B23: 5138 | C23: 149 | D23: 7.56 | E23: 0.004 | F23: 297 | G23: =C23*F23 -> 44253 | H23: 1.01 | I23: 545 | J23: =J22+I23 -> 23000 | L23: =E23-评价标准!M23 -> -0.001 | M23: =N23-评价标准!N23 -> 0.011541073 | N23: =G23/G22 -> 1.0115411
A24: 18
A25: 19
A26: 20

Sheet 02
A2: Lot No. | B2: 2597 | D2: Seed No. | E2: 2580 | G2: Yield Y30 kg | H2: =G22-E4 -> 39390.593
A3: Strain | B3: 167 | D3: Seed m3 | E3: 7.7
A4: Recipe | B4: Diff | D4: Seed Y30 | E4: =43070*7.7/69.1 -> 4799.4067
A5: time | B5: Air m3/h | C5: Volume | D5: pH | E5: Alcohol v/v% | F5: Cell gpl | G5: kg Y30 | H5: GM | I5: RS kg/h | J5: TFS | K5: Remark | L5: DeltaAlcohol | M5: DeltaGM | N5: AutoGM
A6: 0 | B6: 8920 | C6: 89.2 | D6: 4.94 | E6: 0.208 | F6: 61 | G6: 5441 | J6: 300 | L6: =E6-评价标准!M6 -> 0.008
A7: 1 | B7: 9219 | C7: 90.2 | D7: 3.97 | E7: 0.182 | F7: 71 | G7: 6404 | H7: 1.18 | I7: 528 | J7: =J6+I7 -> 828 | K7: 4 | L7: =E7-评价标准!M7 -> -0.068 | M7: =N7-评价标准!N7 -> -0.023010476 | N7: =G7/G6 -> 1.1769895
A8: 2 | B8: 10513 | C8: 91.4 | D8: 4.05 | E8: 0.176 | F8: 83 | G8: 7586 | H8: 1.18 | I8: 657 | J8: =J7+I8 -> 1485 | K8: 3.5 | L8: =E8-评价标准!M8 -> -0.054 | M8: =N8-评价标准!N8 -> -0.21542786 | N8: =G8/G7 -> 1.1845721
A9: 3 | B9: 12942 | C9: 94.6 | D9: 4.25 | E9: 0.157 | F9: 125 | G9: 11825 | H9: 1.56 | I9: 767 | J9: =J8+I9 -> 2252 | K9: 4 | L9: =E9-评价标准!M9 -> -0.043 | M9: =N9-评价标准!N9 -> 0.20879251 | N9: =G9/G8 -> 1.5587925
A10: 4 | B10: 14761 | C10: 96.8 | D10: 4.5 | E10: 0.138 | F10: 151 | G10: 14617 | H10: 1.24 | I10: 895 | J10: =J9+I10 -> 3147 | K10: 3.5 | L10: =E10-评价标准!M10 -> -0.042 | M10: =N10-评价标准!N10 -> -0.093890063 | N10: =G10/G9 -> 1.2361099
A11: 5 | B11: 16713 | C11: 100.3 | D11: 4.64 | E11: 0.155 | F11: 166 | G11: 16650 | H11: 1.14 | I11: 1114 | J11: =J10+I11 -> 4261 | K11: 3 | L11: =E11-评价标准!M11 -> -0.005 | M11: =N11-评价标准!N11 -> -0.16091537 | N11: =G11/G10 -> 1.1390846
A12: 6 | B12: 17277 | C12: 102.9 | D12: 5.14 | E12: 0.107 | F12: 190 | G12: 19551 | H12: 1.17 | I12: 1316 | J12: =J11+I12 -> 5577 | K12: 4.5 | L12: =E12-评价标准!M12 -> -0.033 | M12: =N12-评价标准!N12 -> -0.075765766 | N12: =G12/G11 -> 1.1742342
A13: 7 | B13: 19226 | C13: 107.8 | D13: 5.67 | E13: 0.053 | F13: 206 | G13: 22207 | H13: 1.14 | I13: 1529 | J13: =J12+I13 -> 7106 | K13: 3 | L13: =E13-评价标准!M13 -> -0.077 | M13: =N13-评价标准!N13 -> -0.074150171 | N13: =G13/G12 -> 1.1358498
A14: 8 | B14: 19880 | C14: 112.8 | D14: 6.14 | E14: 0.043 | F14: 227 | G14: 25606 | H14: 1.15 | I14: 1548 | J14: =J13+I14 -> 8654 | K14: 3 | L14: =E14-评价标准!M14 -> -0.077 | M14: =N14-评价标准!N14 -> -0.036940154 | N14: =G14/G13 -> 1.1530598
A15: 9 | B15: 20045 | C15: 117.2 | D15: 6.14 | E15: 0.076 | F15: 242 | G15: 28362 | H15: 1.11 | I15: 1709 | J15: =J14+I15 -> 10363 | K15: 2.5 | L15: =E15-评价标准!M15 -> -0.034 | M15: =N15-评价标准!N15 -> -0.062368976 | N15: =G15/G14 -> 1.107631
A16: 10 | B16: 20048 | C16: 121.4 | D16: 6.27 | E16: 0.067 | F16: 257 | G16: 31200 | H16: 1.1 | I16: 1832 | J16: =J15+I16 -> 12195 | K16: 3 | L16: =E16-评价标准!M16 -> -0.033 | M16: =N16-评价标准!N16 -> -0.049936535 | N16: =G16/G15 -> 1.1000635
A17: 11 | B17: 20190 | C17: 126.4 | D17: 6.43 | E17: 0.093 | F17: 267 | G17: 33749 | H17: 1.08 | I17: 1904 | J17: =J16+I17 -> 14099 | K17: 2 | L17: =E17-评价标准!M17 -> 0.003 | M17: =N17-评价标准!N17 -> -0.048301282 | N17: =G17/G16 -> 1.0816987
A18: 12 | B18: 20070 | C18: 131.2 | D18: 6.46 | E18: 0.069 | F18: 276 | G18: 36211 | H18: 1.07 | I18: 2105 | J18: =J17+I18 -> 16204 | K18: 3 | L18: =E18-评价标准!M18 -> -0.011 | M18: =N18-评价标准!N18 -> -0.03704969 | N18: =G18/G17 -> 1.0729503
... A21: 15 | B21: 18190 | C21: 144.8 | D21: 6.66 | E21: 0.059 | F21: 296 | G21: 42810 | H21: 1.05 | I21: 2194 | J21: =J20+I21 -> 22315 | K21: 3 | L21: =E21-评价标准!M21 -> 0.029 | M21: =N21-评价标准!N21 -> -0.0015576019 | N21: =G21/G20 -> 1.0484424
A22: 16 | B22: 5022 | C22: 147.3 | D22: 7.34 | E22: 0.005 | F22: 300 | G22: 44190 | H22: 1.03 | I22: 685 | J22: =J21+I22 -> 23000 | L22: =E22-评价标准!M22 -> -0.005 | M22: =N22-评价标准!N22 -> 0.012235459 | N22: =G22/G21 -> 1.0322355
A23: 17 | M23: =N23-评价标准!N23 -> -1 | N23: =G23/G22 -> 0
A24: 18
A25: 19
A26: 20

Sheet 03
A2: Lot No. | B2: 2593 | D2: Seed No. | E2: 2580 | G2: Yield Y30 kg | H2: =G23-E4 -> 39066.593
A3: Strain | B3: 167 | D3: Seed m3 | E3: 7.7
A4: Recipe | B4: Diff | D4: Seed Y30 | E4: =43070*E3/69.1 -> 4799.4067
A5: time | B5: Air m3/h | C5: Volume | D5: pH | E5: Alcohol v/v% | F5: Cell gpl | G5: Y30 kg | H5: GM | I5: RS kg/h | J5: TFS | K5: Remark | L5: DeltaAlcohol | M5: DeltaGM | N5: AutoGM
A6: 0 | B6: 9106 | C6: 88.7 | D6: 5.08 | E6: 0.191 | F6: 57 | G6: 5056 | J6: 300 | L6: =E6-评价标准!M6 -> -0.009
A7: 1 | B7: 9202 | C7: 89.7 | D7: 3.91 | E7: 0.177 | F7: 70 | G7: 6270 | H7: 1.24 | I7: 527 | J7: =J6+I7 -> 827 | K7: 4 | L7: =E7-评价标准!M7 -> -0.073 | M7: =N7-评价标准!N7 -> 0.040110759 | N7: =G7/G6 -> 1.2401108
A8: 2 | B8: 10231 | C8: 92.2 | D8: 4.12 | E8: 0.178 | F8: 95 | G8: 8759 | H8: 1.19 | I8: 616 | J8: =J7+I8 -> 1443 | K8: 3 | L8: =E8-评价标准!M8 -> -0.052 | M8: =N8-评价标准!N8 -> -0.003030303 | N8: =G8/G7 -> 1.3969697
A9: 3 | B9: 12507 | C9: 92.3 | D9: 4.31 | E9: 0.11 | F9: 133 | G9: 12409 | H9: 1.42 | I9: 682 | J9: =J8+I9 -> 2125 | K9: 2 | L9: =E9-评价标准!M9 -> -0.09 | M9: =N9-评价标准!N9 -> 0.066714237 | N9: =G9/G8 -> 1.4167142
A10: 4 | B10: 14556 | C10: 96.1 | D10: 4.61 | E10: 0.107 | F10: 147 | G10: 14127 | H10: 1.14 | I10: 1022 | J10: =J9+I10 -> 3147 | K10: 3 | L10: =E10-评价标准!M10 -> -0.073 | M10: =N10-评价标准!N10 -> -0.1915521 | N10: =G10/G9 -> 1.1384479
A11: 5 | B11: 16536 | C11: 98.7 | D11: 4.88 | E11: 0.087 | F11: 169 | G11: 16680 | H11: 1.18 | I11: 1063 | J11: =J10+I11 -> 4210 | K11: 2 | L11: =E11-评价标准!M11 -> -0.073 | M11: =N11-评价标准!N11 -> -0.11928223 | N11: =G11/G10 -> 1.1807178
A12: 6 | B12: 17166 | C12: 102.3 | D12: 5.32 | E12: 0.08 | F12: 189 | G12: 19335 | H12: 1.16 | I12: 1229 | J12: =J11+I12 -> 5439 | K12: 4 | L12: =E12-评价标准!M12 -> -0.06 | M12: =N12-评价标准!N12 -> -0.090827338 | N12: =G12/G11 -> 1.1591727
A13: 7 | B13: 19446 | C13: 107.8 | D13: 6.03 | E13: 0.056 | F13: 211 | G13: 22745 | H13: 1.18 | I13: 1404 | J13: =J12+I13 -> 6843 | K13: 2.5 | L13: =E13-评价标准!M13 -> -0.074 | M13: =N13-评价标准!N13 -> -0.033635893 | N13: =G13/G12 -> 1.1763641
A14: 8 | B14: 20118 | C14: 112 | D14: 6.34 | E14: 0.086 | F14: 228 | G14: 25536 | H14: 1.12 | I14: 1607 | J14: =J13+I14 -> 8450 | K14: 2.5 | L14: =E14-评价标准!M14 -> -0.034 | M14: =N14-评价标准!N14 -> -0.067291712 | N14: =G14/G13 -> 1.1227083
A15: 9 | B15: 19889 | C15: 115.5 | D15: 6.29 | E15: 0.089 | F15: 243 | G15: 28066 | H15: 1.1 | I15: 1591 | J15: =J14+I15 -> 10041 | K15: 2 | L15: =E15-评价标准!M15 -> -0.021 | M15: =N15-评价标准!N15 -> -0.070924185 | N15: =G15/G14 -> 1.0990758
A16: 10 | B16: 19947 | C16: 119.8 | D16: 6.3 | E16: 0.086 | F16: 256 | G16: 30669 | H16: 1.09 | I16: 1792 | J16: =J15+I16 -> 11833 | K16: 4 | L16: =E16-评价标准!M16 -> -0.014 | M16: =N16-评价标准!N16 -> -0.057254329 | N16: =G16/G15 -> 1.0927457
A17: 11 | B17: 20426 | C17: 123 | D17: 6.4 | E17: 0.109 | F17: 270 | G17: 33750 | H17: 1.1 | I17: 1967 | J17: =J16+I17 -> 13800 | K17: 2 | L17: =E17-评价标准!M17 -> 0.019 | M17: =N17-评价标准!N17 -> -0.029540252 | N17: =G17/G16 -> 1.1004597
A18: 12 | B18: 20025 | C18: 129.5 | D18: 6.53 | E18: 0.067 | F18: 278 | G18: 36001 | H18: 1.07 | I18: 1801 | J18: =J17+I18 -> 15601 | K18: 2 | L18: =E18-评价标准!M18 -> -0.013 | M18: =N18-评价标准!N18 -> -0.043303704 | N18: =G18/G17 -> 1.0666963
... A22: 16 | B22: 14892 | C22: 147.2 | D22: 7.44 | E22: 0.016 | F22: 295 | G22: 43424 | H22: 1.03 | I22: 1452 | J22: =J21+I22 -> 22467 | K22: 2 | L22: =E22-评价标准!M22 -> 0.006 | M22: =N22-评价标准!N22 -> 0.0078599664 | N22: =G22/G21 -> 1.02786
A23: 17 | B23: 5061 | C23: 148.7 | D23: 7.6 | E23: 0.004 | F23: 295 | G23: 43866 | H23: 1.01 | I23: 533 | J23: =J22+I23 -> 23000 | L23: =E23-评价标准!M23 -> -0.001 | M23: =N23-评价标准!N23 -> 0.010178703 | N23: =G23/G22 -> 1.0101787
A24: 18
A25: 19
A26: 20

Sheet 04
A2: Lot No. | B2: 2599 | D2: Seed No. | E2: 2580 | G2: Yield Y30 kg | H2: =G23-E4 -> 38892.223
A3: Strain | B3: 167 | D3: Seed m3 | E3: 7.6
A4: Recipe | B4: Diff | D4: Seed Y30 | E4: =43070*E3/69.1 -> 4737.0767
A5: time | B5: Air m3/h | C5: Volume | D5: pH | E5: Alcohol v/v% | F5: Cell gpl | G5: Y30 kg | H5: GM | I5: RS kg/h | J5: TFS | K5: Remark | L5: DeltaAlcohol | M5: DeltaGM | N5: AutoGM
A6: 0 | B6: 8990 | C6: 88.5 | D6: 4.53 | E6: 0.151 | F6: 63 | G6: =C6*F6 -> 5575.5 | J6: 300 | L6: =E6-评价标准!M6 -> -0.049
A7: 1 | B7: 9574 | C7: 89.2 | D7: 4.33 | E7: 0.264 | F7: 73 | G7: =C7*F7 -> 6511.6 | H7: 1.17 | I7: 692 | J7: =J6+I7 -> 992 | K7: 3 | L7: =E7-评价标准!M7 -> 0.014 | M7: =N7-评价标准!N7 -> -0.032104744 | N7: =G7/G6 -> 1.1678953
A8: 2 | B8: 11280 | C8: 91.2 | D8: 4.44 | E8: 0.229 | F8: 82 | G8: =C8*F8 -> 7478.4 | H8: 1.14 | I8: 669 | J8: =J7+I8 -> 1661 | K8: 3 | L8: =E8-评价标准!M8 -> -0.001 | M8: =N8-评价标准!N8 -> -0.25152651 | N8: =G8/G7 -> 1.1484735
A9: 3 | B9: 13318 | C9: 94.6 | D9: 4.34 | E9: 0.166 | F9: 108 | G9: =C9*F9 -> 10216.8 | H9: 1.36 | I9: 770 | J9: =J8+I9 -> 2431 | K9: 3 | L9: =E9-评价标准!M9 -> -0.034 | M9: =N9-评价标准!N9 -> 0.016174583 | N9: =G9/G8 -> 1.3661746
A10: 4 | B10: 15581 | C10: 96.9 | D10: 4.79 | E10: 0.131 | F10: 136 | G10: =C10*F10 -> 13178.4 | H10: 1.29 | I10: 1118 | J10: =J9+I10 -> 3549 | K10: 2 | L10: =E10-评价标准!M10 -> -0.049 | M10: =N10-评价标准!N10 -> -0.040124501 | N10: =G10/G9 -> 1.2898755
A11: 5 | B11: 16712 | C11: 101 | D11: 5.05 | E11: 0.138 | F11: 163 | G11: =C11*F11 -> 16463 | H11: 1.25 | I11: 1255 | J11: =J10+I11 -> 4804 | K11: 2 | L11: =E11-评价标准!M11 -> -0.022 | M11: =N11-评价标准!N11 -> -0.050758817 | N11: =G11/G10 -> 1.2492412
A12: 6 | B12: 17952 | C12: 104 | D12: 5.62 | E12: 0.153 | F12: 187 | G12: =C12*F12 -> 19448 | H12: 1.18 | I12: 1188 | J12: =J11+I12 -> 5992 | K12: 2 | L12: =E12-评价标准!M12 -> 0.013 | M12: =N12-评价标准!N12 -> -0.068684322 | N12: =G12/G11 -> 1.1813157
A13: 7 | B13: 19384 | C13: 109.4 | D13: 5.98 | E13: 0.113 | F13: 204 | G13: =C13*F13 -> 22317.6 | H13: 1.15 | I13: 1338 | J13: =J12+I13 -> 7330 | K13: 3 | L13: =E13-评价标准!M13 -> -0.017 | M13: =N13-评价标准!N13 -> -0.062447552 | N13: =G13/G12 -> 1.1475524
A14: 8 | B14: 20015 | C14: 113 | D14: 6.14 | E14: 0.119 | F14: 220 | G14: =C14*F14 -> 24860 | H14: 1.11 | I14: 1601 | J14: =J13+I14 -> 8931 | K14: 3 | L14: =E14-评价标准!M14 -> -0.001 | M14: =N14-评价标准!N14 -> -0.076080941 | N14: =G14/G13 -> 1.1139191
A15: 9 | B15: 16696 | C15: 117.3 | D15: 6.2 | E15: 0.087 | F15: 235 | G15: =C15*F15 -> 27565.5 | H15: 1.11 | I15: 1753 | J15: =J14+I15 -> 10684 | K15: 2 | L15: =E15-评价标准!M15 -> -0.023 | M15: =N15-评价标准!N15 -> -0.061170555 | N15: =G15/G14 -> 1.1088294
A16: 10 | B16: 20067 | C16: 121.6 | D16: 6.27 | E16: 0.393 | F16: 250 | G16: =C16*F16 -> 30400 | H16: 1.1 | I16: 1728 | J16: =J15+I16 -> 12412 | K16: 3 | L16: =E16-评价标准!M16 -> 0.293 | M16: =N16-评价标准!N16 -> -0.04717219 | N16: =G16/G15 -> 1.1028278
A17: 11 | B17: 20026 | C17: 125.8 | D17: 6.4 | E17: 0.064 | F17: 263 | G17: =C17*F17 -> 33085.4 | H17: 1.09 | I17: 1706 | J17: =J16+I17 -> 14118 | K17: 3.5 | L17: =E17-评价标准!M17 -> -0.026 | M17: =N17-评价标准!N17 -> -0.041664474 | N17: =G17/G16 -> 1.0883355
A18: 12 | B18: 20079 | C18: 131.1 | D18: 6.39 | E18: 0.066 | F18: 275 | G18: =C18*F18 -> 36052.5 | H18: 1.09 | I18: 1962 | J18: =J17+I18 -> 16080 | K18: 3 | L18: =E18-评价标准!M18 -> -0.014 | M18: =N18-评价标准!N18 -> -0.02031996 | N18: =G18/G17 -> 1.08968
... A22: 16 | B22: 14931 | C22: 146.9 | D22: 7.18 | E22: 0.025 | F22: 297 | G22: =C22*F22 -> 43629.3 | H22: 1.03 | I22: 999 | J22: =J21+I22 -> 22773 | K22: 2.5 | L22: =E22-评价标准!M22 -> 0.015 | M22: =N22-评价标准!N22 -> 0.010633674 | N22: =G22/G21 -> 1.0306337
A23: 17 | B23: 49944 | C23: 146.9 | D23: 7.38 | E23: 0.01 | F23: 297 | G23: =C23*F23 -> 43629.3 | H23: 1 | I23: 127 | J23: =J22+I23 -> 22900 | L23: =E23-评价标准!M23 -> 0.005 | M23: =N23-评价标准!N23 -> 0 | N23: =G23/G22 -> 1
A24: 18
A25: 19
A26: 20

Sheet 05
A2: Lot No. | B2: 2598 | D2: Seed No. | E2: 2580 | G2: Yield Y30 kg | H2: =G23-E4 -> 39068.923
A3: Strain | B3: 167 | D3: Seed m3 | E3: 7.6
A4: Recipe | B4: Diff | D4: Seed Y30 | E4: =43070*E3/69.1 -> 4737.0767
A5: time | B5: Air m3/h | C5: Volume | D5: pH | E5: Alcohol v/v% | F5: Cell gpl | G5: Y30 kg | H5: GM | I5: RS kg/h | J5: TFS | K5: Remark | L5: DeltaAlcohol | M5: DeltaGM | N5: AutoGM
A6: 0 | B6: 9027 | C6: 883 | D6: 5.17 | E6: 0.155 | F6: 62 | G6: 5475 | J6: 300 | L6: =E6-评价标准!M6 -> -0.045
A7: 1 | B7: 8972 | C7: 897 | D7: 4.61 | E7: 0.227 | F7: 72 | G7: 6458 | H7: 1.18 | I7: 508 | J7: =J6+I7 -> 808 | K7: 3.5 | L7: =E7-评价标准!M7 -> -0.023 | M7: =N7-评价标准!N7 -> -0.020456621 | N7: =G7/G6 -> 1.1795434
A8: 2 | B8: 10016 | C8: 923 | D8: 4.31 | E8: 0.225 | F8: 104 | G8: 9599 | H8: 1.49 | I8: 606 | J8: =J7+I8 -> 1414 | K8: 4 | L8: =E8-评价标准!M8 -> -0.005 | M8: =N8-评价标准!N8 -> 0.08637349 | N8: =G8/G7 -> 1.4863735
A9: 3 | B9: 12076 | C9: 942 | D9: 4.41 | E9: 0.192 | F9: 122 | G9: 11492 | H9: 1.2 | I9: 741 | J9: =J8+I9 -> 2155 | K9: 4 | L9: =E9-评价标准!M9 -> -0.008 | M9: =N9-评价标准!N9 -> -0.15279196 | N9: =G9/G8 -> 1.197208
A10: 4 | B10: 14267 | C10: 961 | D10: 4.55 | E10: 0.146 | F10: 140 | G10: 13454 | H10: 1.17 | I10: 819 | J10: =J9+I10 -> 2974 | K10: 3.5 | L10: =E10-评价标准!M10 -> -0.034 | M10: =N10-评价标准!N10 -> -0.15927254 | N10: =G10/G9 -> 1.1707275
A11: 5 | B11: 16566 | C11: 987 | D11: 4.78 | E11: 0.104 | F11: 158 | G11: 15595 | H11: 1.16 | I11: 1079 | J11: =J10+I11 -> 4053 | K11: 3 | L11: =E11-评价标准!M11 -> -0.056 | M11: =N11-评价标准!N11 -> -0.14086517 | N11: =G11/G10 -> 1.1591348
A12: 6 | B12: 17386 | C12: 1020 | D12: 5.23 | E12: 0.088 | F12: 176 | G12: 17952 | H12: 1.15 | I12: 1400 | J12: =J11+I12 -> 5453 | K12: 3.5 | L12: =E12-评价标准!M12 -> -0.052 | M12: =N12-评价标准!N12 -> -0.098861815 | N12: =G12/G11 -> 1.1511382
A13: 7 | B13: 19026 | C13: 1059 | D13: 5.77 | E13: 0.059 | F13: 198 | G13: 20968 | H13: 1.17 | I13: 1425 | J13: =J12+I13 -> 6878 | K13: 2 | L13: =E13-评价标准!M13 -> -0.071 | M13: =N13-评价标准!N13 -> -0.041996435 | N13: =G13/G12 -> 1.1680036
A14: 8 | B14: 19894 | C14: 1122 | D14: 6.16 | E14: 0.079 | F14: 213 | G14: 23898 | H14: 1.14 | I14: 1780 | J14: =J13+I14 -> 8658 | K14: 3 | L14: =E14-评价标准!M14 -> -0.041 | M14: =N14-评价标准!N14 -> -0.050263258 | N14: =G14/G13 -> 1.1397367
A15: 9 | B15: 19794 | C15: 1160 | D15: 6.19 | E15: 0.074 | F15: 228 | G15: 26448 | H15: 1.1 | I15: 1643 | J15: =J14+I15 -> 10301 | K15: 3 | L15: =E15-评价标准!M15 -> -0.036 | M15: =N15-评价标准!N15 -> -0.06329651 | N15: =G15/G14 -> 1.1067035
A16: 10 | B16: 20240 | C16: 1206 | D16: 6.2 | E16: 0.076 | F16: 245 | G16: 29547 | H16: 1.18 | I16: 1884 | J16: =J15+I16 -> 12185 | K16: 4 | L16: =E16-评价标准!M16 -> -0.024 | M16: =N16-评价标准!N16 -> -0.032826679 | N16: =G16/G15 -> 1.1171733
A17: 11 | B17: 19463 | C17: 1249 | D17: 4.79 | E17: 0.058 | F17: 266 | G17: 33223 | H17: 1.12 | I17: 1819 | J17: =J16+I17 -> 14004 | K17: 3 | L17: =E17-评价标准!M17 -> -0.032 | M17: =N17-评价标准!N17 -> -0.0055880462 | N17: =G17/G16 -> 1.124412
A18: 12 | B18: 19970 | C18: 1283 | D18: 6.48 | E18: 0.043 | F18: 278 | G18: 35667 | H18: 1.07 | I18: 1900 | J18: =J17+I18 -> 15904 | K18: 3.5 | L18: =E18-评价标准!M18 -> -0.037 | M18: =N18-评价标准!N18 -> -0.036436505 | N18: =G18/G17 -> 1.0735635
... A22: 16 | B22: 13941 | C22: 1467 | D22: 7.22 | E22: 0.018 | F22: 298 | G22: 43716 | H22: 1.03 | I22: 1215 | J22: =J21+I22 -> 22827 | K22: 2 | L22: =E22-评价标准!M22 -> 0.008 | M22: =N22-评价标准!N22 -> 0.005860046 | N22: =G22/G21 -> 1.02586
A23: 17 | B23: 4990 | C23: 1470 | D23: 7.36 | E23: 0.206 | F23: 298 | G23: 43806 | H23: 1 | I23: 231 | J23: =J22+I23 -> 23058 | L23: =E23-评价标准!M23 -> 0.201 | M23: =N23-评价标准!N23 -> 0.0020587428 | N23: =G23/G22 -> 1.0020587
A24: 18
A25: 19
A26: 20

Sheet 06
A2: Lot No. | B2: 2602 | D2: Seed No. | E2: 2580 | G2: Yield Y30 kg | H2: =G23-E4 -> 38383.863
A3: Strain | B3: 167 | D3: Seed m3 | E3: 7.8
A4: Recipe | B4: Diff | D4: Seed Y30 | E4: =43070*E3/69.1 -> 4861.7366
A5: time | B5: Air m3/h | C5: Volume | D5: pH | E5: Alcohol v/v% | F5: Cell gpl | G5: Y30 kg | H5: GM | I5: RS kg/h | J5: TFS | K5: Remark | L5: DeltaAlcohol | M5: DeltaGM | N5: AutoGM
A6: 0 | B6: 9225 | C6: 87.7 | D6: 5.1 | E6: 0.207 | F6: 62 | G6: =F6*C6 -> 5437.4 | J6: 300 | L6: =E6-评价标准!M6 -> 0.007
A7: 1 | B7: 9310 | C7: 90 | D7: 4.62 | E7: 0.25 | F7: 71 | G7: =F7*C7 -> 6390 | H7: 1.17 | I7: 726 | J7: =J6+I7 -> 1026 | K7: 5 | L7: =E7-评价标准!M7 -> 0 | M7: =N7-评价标准!N7 -> -0.024805973 | N7: =G7/G6 -> 1.175194
A8: 2 | B8: 10734 | C8: 92.4 | D8: 4.18 | E8: 0.232 | F8: 91 | G8: =F8*C8 -> 8408.4 | H8: 1.32 | I8: 594 | J8: =J7+I8 -> 1620 | K8: 2 | L8: =E8-评价标准!M8 -> 0.002 | M8: =N8-评价标准!N8 -> -0.084131455 | N8: =G8/G7 -> 1.3158685
A9: 3 | B9: 13067 | C9: 92.8 | D9: 4.15 | E9: 0.195 | F9: 115 | G9: =F9*C9 -> 10672 | H9: 1.27 | I9: 700 | J9: =J8+I9 -> 2320 | K9: 3 | L9: =E9-评价标准!M9 -> -0.005 | M9: =N9-评价标准!N9 -> -0.080793017 | N9: =G9/G8 -> 1.269207
A10: 4 | B10: 15140 | C10: 96.3 | D10: 4.43 | E10: 0.099 | F10: 138 | G10: =F10*C10 -> 13289.4 | H10: 1.25 | I10: 892 | J10: =J9+I10 -> 3212 | K10: 2 | L10: =E10-评价标准!M10 -> -0.081 | M10: =N10-评价标准!N10 -> -0.084741379 | N10: =G10/G9 -> 1.2452586
A11: 5 | B11: 16675 | C11: 99.3 | D11: 4.78 | E11: 0.107 | F11: 164 | G11: =F11*C11 -> 16285.2 | H11: 1.22 | I11: 1185 | J11: =J10+I11 -> 4397 | K11: 4 | L11: =E11-评价标准!M11 -> -0.053 | M11: =N11-评价标准!N11 -> -0.074572215 | N11: =G11/G10 -> 1.2254278
A12: 6 | B12: 17702 | C12: 102.2 | D12: 5.32 | E12: 0.126 | F12: 183 | G12: =F12*C12 -> 18702.6 | H12: 1.13 | I12: 1246 | J12: =J11+I12 -> 5643 | K12: 4 | L12: =E12-评价标准!M12 -> -0.014 | M12: =N12-评价标准!N12 -> -0.10155847 | N12: =G12/G11 -> 1.1484415
A13: 7 | B13: 19265 | C13: 106.1 | D13: 5.88 | E13: 0.116 | F13: 204 | G13: =F13*C13 -> 21644.4 | H13: 1.16 | I13: 1475 | J13: =J12+I13 -> 7118 | K13: 3 | L13: =E13-评价标准!M13 -> -0.014 | M13: =N13-评价标准!N13 -> -0.052706362 | N13: =G13/G12 -> 1.1572936
A14: 8 | B14: 19942 | C14: 111.2 | D14: 6.1 | E14: 0.093 | F14: 221 | G14: =F14*C14 -> 24575.2 | H14: 1.14 | I14: 1543 | J14: =J13+I14 -> 8661 | K14: 3 | L14: =E14-评价标准!M14 -> -0.027 | M14: =N14-评价标准!N14 -> -0.054593151 | N14: =G14/G13 -> 1.1354068
A15: 9 | B15: 20064 | C15: 115 | D15: 6.1 | E15: 0.04 | F15: 233 | G15: =F15*C15 -> 26795 | H15: 1.09 | I15: 1597 | J15: =J14+I15 -> 10258 | K15: 2.5 | L15: =E15-评价标准!M15 -> -0.07 | M15: =N15-评价标准!N15 -> -0.079673166 | N15: =G15/G14 -> 1.0903268
A16: 10 | B16: 20309 | C16: 120 | D16: 6.23 | E16: 0.087 | F16: 250 | G16: =F16*C16 -> 30000 | H16: 1.12 | I16: 1980 | J16: =J15+I16 -> 12238 | K16: 3 | L16: =E16-评价标准!M16 -> -0.013 | M16: =N16-评价标准!N16 -> -0.030388132 | N16: =G16/G15 -> 1.1196119
A17: 11 | B17: 19925 | C17: 123.8 | D17: 6.33 | E17: 0.064 | F17: 264 | G17: =F17*C17 -> 32683.2 | H17: 1.08 | I17: 1715 | J17: =J16+I17 -> 13953 | K17: 3 | L17: =E17-评价标准!M17 -> -0.026 | M17: =N17-评价标准!N17 -> -0.04056 | N17: =G17/G16 -> 1.08944
A18: 12 | B18: 19948 | C18: 127.9 | D18: 6.4 | E18: 0.031 | F18: 277 | G18: =F18*C18 -> 35428.3 | H18: 1.08 | I18: 1841 | J18: =J17+I18 -> 15794 | K18: 3 | L18: =E18-评价标准!M18 -> -0.049 | M18: =N18-评价标准!N18 -> -0.026008836 | N18: =G18/G17 -> 1.0839912
... A22: 16 | B22: 14936 | C22: 144.7 | D22: 7.46 | E22: 0.012 | F22: 296 | G22: =F22*C22 -> 42831.2 | H22: 1.03 | I22: 1306 | J22: =J21+I22 -> 22619 | K22: 3.5 | L22: =E22-评价标准!M22 -> 0.002 | M22: =N22-评价标准!N22 -> 0.0081182339 | N22: =G22/G21 -> 1.0281182
A23: 17 | B23: 5018 | C23: 146.1 | D23: 7.62 | E23: 0.005 | F23: 296 | G23: =F23*C23 -> 43245.6 | H23: 1.01 | I23: 381 | J23: =J22+I23 -> 23000 | L23: =E23-评价标准!M23 -> 0 | M23: =N23-评价标准!N23 -> 0.00967519 | N23: =G23/G22 -> 1.0096752
A24: 18
A25: 19
A26: 20

Sheet 07
A2: Lot No. | B2: 2607 | D2: Seed No. | E2: 2580 | G2: Yield Y30 kg | H2: =G23-E4 -> 38562.263
A3: Strain | B3: 167 | D3: Seed m3 | E3: 7.8
A4: Recipe | B4: Diff | D4: Seed Y30 | E4: =43070*E3/69.1 -> 4861.7366
A5: time | B5: Air m3/h | C5: Volume | D5: pH | E5: Alcohol v/v% | F5: Cell gpl | G5: Y30 kg | H5: GM | I5: RS kg/h | J5: TFS | K5: Remark | L5: DeltaAlcohol | M5: DeltaGM | N5: AutoGM
A6: 0 | B6: 9362 | C6: 88.7 | D6: 4.22 | E6: 0.2 | F6: 59 | G6: =F6*C6 -> 5233.3 | J6: 300 | L6: =E6-评价标准!M6 -> 0
A7: 1 | B7: 9198 | C7: 89.8 | D7: 4.6 | E7: 0.275 | F7: 69 | G7: =F7*C7 -> 6196.2 | H7: 1.18 | I7: 611 | J7: =J6+I7 -> 911 | K7: 4 | L7: =E7-评价标准!M7 -> 0.025 | M7: =N7-评价标准!N7 -> -0.016005197 | N7: =G7/G6 -> 1.1839948
A8: 2 | B8: 10109 | C8: 92.8 | D8: 4.12 | E8: 0.26 | F8: 90 | G8: =F8*C8 -> 8352 | H8: 1.34 | I8: 626 | J8: =J7+I8 -> 1537 | K8: 4 | L8: =E8-评价标准!M8 -> 0.03 | M8: =N8-评价标准!N8 -> -0.05207708 | N8: =G8/G7 -> 1.3479229
A9: 3 | B9: 12443 | C9: 93.3 | D9: 4.03 | E9: 0.135 | F9: 121 | G9: =F9*C9 -> 11289.3 | H9: 1.35 | I9: 576 | J9: =J8+I9 -> 2113 | K9: 2 | L9: =E9-评价标准!M9 -> -0.065 | M9: =N9-评价标准!N9 -> 0.0016882184 | N9: =G9/G8 -> 1.3516882
A10: 4 | B10: 14895 | C10: 95.8 | D10: 4.27 | E10: 0.049 | F10: 143 | G10: =F10*C10 -> 13699.4 | H10: 1.21 | I10: 764 | J10: =J9+I10 -> 2877 | K10: 3 | L10: =E10-评价标准!M10 -> -0.131 | M10: =N10-评价标准!N10 -> -0.11651466 | N10: =G10/G9 -> 1.2134853
A11: 5 | B11: 16561 | C11: 97.8 | D11: 4.65 | E11: 0.072 | F11: 165 | G11: =F11*C11 -> 16137 | H11: 1.18 | I11: 1088 | J11: =J10+I11 -> 3965 | K11: 3 | L11: =E11-评价标准!M11 -> -0.088 | M11: =N11-评价标准!N11 -> -0.1220652 | N11: =G11/G10 -> 1.1779348
A12: 6 | B12: 17311 | C12: 101.8 | D12: 5.4 | E12: 0.11 | F12: 180 | G12: =F12*C12 -> 18324 | H12: 1.14 | I12: 1300 | J12: =J11+I12 -> 5265 | K12: 3.5 | L12: =E12-评价标准!M12 -> -0.03 | M12: =N12-评价标准!N12 -> -0.11447295 | N12: =G12/G11 -> 1.135527
A13: 7 | B13: 19417 | C13: 104.4 | D13: 6 | E13: 0.098 | F13: 200 | G13: =F13*C13 -> 20880 | H13: 1.14 | I13: 1244 | J13: =J12+I13 -> 6509 | K13: 3 | L13: =E13-评价标准!M13 -> -0.032 | M13: =N13-评价标准!N13 -> -0.070510806 | N13: =G13/G12 -> 1.1394892
A14: 8 | B14: 20116 | C14: 109.5 | D14: 5.24 | E14: 0.062 | F14: 212 | G14: =F14*C14 -> 23214 | H14: 1.11 | I14: 1427 | J14: =J13+I14 -> 7936 | K14: 3 | L14: =E14-评价标准!M14 -> -0.058 | M14: =N14-评价标准!N14 -> -0.078218391 | N14: =G14/G13 -> 1.1117816
A15: 9 | B15: 20013 | C15: 114.2 | D15: 6.2 | E15: 0.072 | F15: 231 | G15: =F15*C15 -> 26380.2 | H15: 1.14 | I15: 1610 | J15: =J14+I15 -> 9546 | K15: 3.5 | L15: =E15-评价标准!M15 -> -0.038 | M15: =N15-评价标准!N15 -> -0.033608167 | N15: =G15/G14 -> 1.1363918
A16: 10 | B16: 20092 | C16: 118.1 | D16: 6.25 | E16: 0.055 | F16: 250 | G16: =F16*C16 -> 29525 | H16: 1.12 | I16: 1715 | J16: =J15+I16 -> 11261 | K16: 4 | L16: =E16-评价标准!M16 -> -0.045 | M16: =N16-评价标准!N16 -> -0.03078938 | N16: =G16/G15 -> 1.1192106
A17: 11 | B17: 20067 | C17: 122.3 | D17: 6.42 | E17: 0.072 | F17: 266 | G17: =F17*C17 -> 32531.8 | H17: 1.1 | I17: 1915 | J17: =J16+I17 -> 13176 | K17: 3 | L17: =E17-评价标准!M17 -> -0.018 | M17: =N17-评价标准!N17 -> -0.028160881 | N17: =G17/G16 -> 1.1018391
A18: 12 | B18: 19846 | C18: 127 | D18: 6.49 | E18: 0.03 | F18: 276 | G18: =F18*C18 -> 35052 | H18: 1.08 | I18: 1746 | J18: =J17+I18 -> 14922 | K18: 3 | L18: =E18-评价标准!M18 -> -0.05 | M18: =N18-评价标准!N18 -> -0.032531185 | N18: =G18/G17 -> 1.0774688
... A22: 16 | B22: 17578 | C22: 142 | D22: 6.94 | E22: 0.015 | F22: 295 | G22: =F22*C22 -> 41890 | H22: 1.04 | I22: 1888 | J22: =J21+I22 -> 22226 | K22: 3 | L22: =E22-评价标准!M22 -> 0.005 | M22: =N22-评价标准!N22 -> -0.00080834623 | N22: =G22/G21 -> 1.0191917
A23: 17 | B23: 4961 | C23: 147.2 | D23: 7.61 | E23: 0.006 | F23: 295 | G23: =F23*C23 -> 43424 | H23: 1.02 | I23: 825 | J23: =J22+I23 -> 23051 | L23: =E23-评价标准!M23 -> 0.001 | M23: =N23-评价标准!N23 -> 0.036619718 | N23: =G23/G22 -> 1.0366197
A24: 18
A25: 19
A26: 20

Sheet 08
A2: Lot No. | B2: 2608 | D2: Seed No. | E2: 2580 | G2: Yield Y30 kg | H2: =G23-E4 -> 39455.723
A3: Strain | B3: 167 | D3: Seed m3 | E3: 7.6
A4: Recipe | B4: Diff | D4: Seed Y30 | E4: =43070*E3/69.1 -> 4737.0767
A5: time | B5: Air m3/h | C5: Volume | D5: pH | E5: Alcohol v/v% | F5: Cell gpl | G5: Y30 kg | H5: GM | I5: RS kg/h | J5: TFS | K5: Remark | L5: DeltaAlcohol | M5: DeltaGM | N5: AutoGM
A6: 0 | B6: 9757 | C6: 89.9 | D6: 4.36 | E6: 0.191 | F6: 67 | G6: =F6*C6 -> 6023.3 | J6: 300 | L6: =E6-评价标准!M6 -> -0.009
A7: 1 | B7: 9209 | C7: 90.1 | D7: 4.13 | E7: 0.255 | F7: 74 | G7: =F7*C7 -> 6667.4 | H7: 1.11 | I7: 469 | J7: =J6+I7 -> 769 | K7: 4 | L7: =E7-评价标准!M7 -> 0.005 | M7: =N7-评价标准!N7 -> -0.093065263 | N7: =G7/G6 -> 1.1069347
A8: 2 | B8: 9983 | C8: 91.5 | D8: 4.09 | E8: 0.178 | F8: 93 | G8: =F8*C8 -> 8509.5 | H8: 1.28 | I8: 521 | J8: =J7+I8 -> 1290 | K8: 3.5 | L8: =E8-评价标准!M8 -> -0.052 | M8: =N8-评价标准!N8 -> -0.12371539 | N8: =G8/G7 -> 1.2762846
A9: 3 | B9: 12254 | C9: 95 | D9: 4.37 | E9: 0.151 | F9: 125 | G9: =F9*C9 -> 11875 | H9: 1.4 | I9: 734 | J9: =J8+I9 -> 2024 | K9: 4 | L9: =E9-评价标准!M9 -> -0.049 | M9: =N9-评价标准!N9 -> 0.045499148 | N9: =G9/G8 -> 1.3954991
A10: 4 | B10: 14340 | C10: 96.6 | D10: 4.61 | E10: 0.127 | F10: 148 | G10: =F10*C10 -> 14296.8 | H10: 1.2 | I10: 946 | J10: =J9+I10 -> 2970 | K10: 3.5 | L10: =E10-评价标准!M10 -> -0.053 | M10: =N10-评价标准!N10 -> -0.12605895 | N10: =G10/G9 -> 1.2039411
A11: 5 | B11: 16504 | C11: 100.5 | D11: 4.96 | E11: 0.145 | F11: 161 | G11: =F11*C11 -> 16180.5 | H11: 1.13 | I11: 1227 | J11: =J10+I11 -> 4197 | K11: 3 | L11: =E11-评价标准!M11 -> -0.015 | M11: =N11-评价标准!N11 -> -0.16824324 | N11: =G11/G10 -> 1.1317568
A12: 6 | B12: 16551 | C12: 103.3 | D12: 5.39 | E12: 0.127 | F12: 180 | G12: =F12*C12 -> 18594 | H12: 1.15 | I12: 1121 | J12: =J11+I12 -> 5318 | K12: 3.5 | L12: =E12-评价标准!M12 -> -0.013 | M12: =N12-评价标准!N12 -> -0.10083897 | N12: =G12/G11 -> 1.149161
A13: 7 | B13: 19050 | C13: 107.7 | D13: 5.83 | E13: 0.141 | F13: 200 | G13: =F13*C13 -> 21540 | H13: 1.16 | I13: 1306 | J13: =J12+I13 -> 6624 | K13: 3 | L13: =E13-评价标准!M13 -> 0.011 | M13: =N13-评价标准!N13 -> -0.051561794 | N13: =G13/G12 -> 1.1584382
A14: 8 | B14: 19937 | C14: 112.2 | D14: 6.07 | E14: 0.114 | F14: 215 | G14: =F14*C14 -> 24123 | H14: 1.12 | I14: 1478 | J14: =J13+I14 -> 8102 | K14: 3 | L14: =E14-评价标准!M14 -> -0.006 | M14: =N14-评价标准!N14 -> -0.070083565 | N14: =G14/G13 -> 1.1199164
A15: 9 | B15: 19993 | C15: 116.4 | D15: 6.14 | E15: 0.103 | F15: 230 | G15: =F15*C15 -> 26772 | H15: 1.11 | I15: 1691 | J15: =J14+I15 -> 9793 | K15: 3.5 | L15: =E15-评价标准!M15 -> -0.007 | M15: =N15-评价标准!N15 -> -0.060187788 | N15: =G15/G14 -> 1.1098122
A16: 10 | B16: 19977 | C16: 121 | D16: 6.17 | E16: 0.108 | F16: 244 | G16: =F16*C16 -> 29524 | H16: 1.1 | I16: 1755 | J16: =J15+I16 -> 11548 | K16: 4 | L16: =E16-评价标准!M16 -> 0.008 | M16: =N16-评价标准!N16 -> -0.047206036 | N16: =G16/G15 -> 1.102794
A17: 11 | B17: 19981 | C17: 124.8 | D17: 6.36 | E17: 0.096 | F17: 260 | G17: =F17*C17 -> 32448 | H17: 1.1 | I17: 1730 | J17: =J16+I17 -> 13278 | K17: 3.5 | L17: =E17-评价标准!M17 -> 0.006 | M17: =N17-评价标准!N17 -> -0.030961929 | N17: =G17/G16 -> 1.0990381
A18: 12 | B18: 19842 | C18: 129.9 | D18: 6.47 | E18: 0.082 | F18: 274 | G18: =F18*C18 -> 35592.6 | H18: 1.1 | I18: 1962 | J18: =J17+I18 -> 15240 | K18: 4 | L18: =E18-评价标准!M18 -> 0.002 | M18: =N18-评价标准!N18 -> -0.013088018 | N18: =G18/G17 -> 1.096912
... A22: 16 | B22: 15089 | C22: 148.3 | D22: 7.11 | E22: 0.028 | F22: 296 | G22: =F22*C22 -> 43896.8 | H22: 1.02 | I22: 1527 | J22: =J21+I22 -> 22516 | K22: 3 | L22: =E22-评价标准!M22 -> 0.018 | M22: =N22-评价标准!N22 -> 0.0041712707 | N22: =G22/G21 -> 1.0241713
A23: 17 | B23: 5001 | C23: 149.3 | D23: 7.75 | E23: 0.003 | F23: 296 | G23: =F23*C23 -> 44192.8 | H23: 1 | I23: 483 | J23: =J22+I23 -> 22999 | L23: =E23-评价标准!M23 -> -0.002 | M23: =N23-评价标准!N23 -> 0.0067430883 | N23: =G23/G22 -> 1.0067431
A24: 18
A25: 19
A26: 20

Sheet 09
A2: Lot No. | B2: 2614 | D2: Seed No. | E2: 2596 | G2: Yield Y30 kg | H2: =G23-E4 -> 38727.955
A3: Strain | B3: 167 | D3: Seed m3 | E3: 7.4
A4: Recipe | B4: Diff | D4: Seed Y30 | E4: =42431*E3/66.5 -> 4721.6451
A5: time | B5: Air m3/h | C5: Volume | D5: pH | E5: Alcohol v/v% | F5: Cell gpl | G5: Y30 kg | H5: GM | I5: RS kg/h | J5: TFS | K5: Remark | L5: DeltaAlcohol | M5: DeltaGM | N5: AutoGM
A6: 0 | B6: 9503 | C6: 90 | D6: 5.5 | E6: 0.151 | F6: 62 | G6: =F6*C6 -> 5580 | J6: 300 | L6: =E6-评价标准!M6 -> -0.049
A7: 1 | B7: 9170 | C7: 90.7 | D7: 4.53 | E7: 0.212 | F7: 69 | G7: =F7*C7 -> 6258.3 | H7: 1.12 | I7: 526 | J7: 826 | K7: 4 | L7: =E7-评价标准!M7 -> -0.038 | M7: =N7-评价标准!N7 -> -0.07844086 | N7: =G7/G6 -> 1.1215591
A8: 2 | B8: 10169 | C8: 92.8 | D8: 4.04 | E8: 0.191 | F8: 90 | G8: =F8*C8 -> 8352 | H8: 1.33 | I8: 521 | J8: 1347 | K8: 4 | L8: =E8-评价标准!M8 -> -0.039 | M8: =N8-评价标准!N8 -> -0.065452279 | N8: =G8/G7 -> 1.3345477
A9: 3 | B9: 12200 | C9: 94.4 | D9: 3.98 | E9: 0.134 | F9: 121 | G9: =F9*C9 -> 11422.4 | H9: 1.37 | I9: 588 | J9: 1935 | K9: 3 | L9: =E9-评价标准!M9 -> -0.066 | M9: =N9-评价标准!N9 -> 0.017624521 | N9: =G9/G8 -> 1.3676245
A10: 4 | B10: 14408 | C10: 96.3 | D10: 4.22 | E10: 0.102 | F10: 142 | G10: =F10*C10 -> 13674.6 | H10: 1.2 | I10: 868 | J10: 2803 | K10: 3 | L10: =E10-评价标准!M10 -> -0.078 | M10: =N10-评价标准!N10 -> -0.13282603 | N10: =G10/G9 -> 1.197174
A11: 5 | B11: 16328 | C11: 99.1 | D11: 4.62 | E11: 0.063 | F11: 169 | G11: =F11*C11 -> 16747.9 | H11: 1.22 | I11: 1201 | J11: 4004 | K11: 3.5 | L11: =E11-评价标准!M11 -> -0.097 | M11: =N11-评价标准!N11 -> -0.075254852 | N11: =G11/G10 -> 1.2247451
A12: 6 | B12: 17298 | C12: 103.2 | D12: 5.24 | E12: 0.104 | F12: 183 | G12: =F12*C12 -> 18885.6 | H12: 1.13 | I12: 1475 | J12: 5479 | K12: 3.5 | L12: =E12-评价标准!M12 -> -0.036 | M12: =N12-评价标准!N12 -> -0.12236012 | N12: =G12/G11 -> 1.1276399
A13: 7 | B13: 19263 | C13: 106.9 | D13: 5.99 | E13: 0.15 | F13: 196 | G13: =F13*C13 -> 20952.4 | H13: 1.11 | I13: 1437 | J13: 6916 | K13: 3 | L13: =E13-评价标准!M13 -> 0.02 | M13: =N13-评价标准!N13 -> -0.10056212 | N13: =G13/G12 -> 1.1094379
A14: 8 | B14: 19866 | C14: 112.4 | D14: 6.27 | E14: 0.116 | F14: 213 | G14: =F14*C14 -> 23941.2 | H14: 1.14 | I14: 1406 | J14: 8322 | K14: 3.5 | L14: =E14-评价标准!M14 -> -0.004 | M14: =N14-评价标准!N14 -> -0.047352857 | N14: =G14/G13 -> 1.1426471
A15: 9 | B15: 20040 | C15: 115.7 | D15: 6.26 | E15: 0.093 | F15: 224 | G15: =F15*C15 -> 25916.8 | H15: 1.08 | I15: 1561 | J15: 9883 | K15: 3.5 | L15: =E15-评价标准!M15 -> -0.017 | M15: =N15-评价标准!N15 -> -0.087481162 | N15: =G15/G14 -> 1.0825188
A16: 10 | B16: 20132 | C16: 120 | D16: 6.26 | E16: 0.039 | F16: 240 | G16: =F16*C16 -> 28800 | H16: 1.11 | I16: 1772 | J16: 11655 | K16: 3 | L16: =E16-评价标准!M16 -> -0.061 | M16: =N16-评价标准!N16 -> -0.038751698 | N16: =G16/G15 -> 1.1112483
A17: 11 | B17: 19944 | C17: 125.1 | D17: 6.33 | E17: 0.021 | F17: 258 | G17: =F17*C17 -> 32275.8 | H17: 1.12 | I17: 1981 | J17: 13634 | K17: 4 | L17: =E17-评价标准!M17 -> -0.069 | M17: =N17-评价标准!N17 -> -0.0093125 | N17: =G17/G16 -> 1.1206875
A18: 12 | B18: 19962 | C18: 129.6 | D18: 6.49 | E18: 0.023 | F18: 271 | G18: =F18*C18 -> 35121.6 | H18: 1.09 | I18: 1973 | J18: 15541 | K18: 3 | L18: =E18-评价标准!M18 -> -0.057 | M18: =N18-评价标准!N18 -> -0.021828677 | N18: =G18/G17 -> 1.0881713
... A22: 16 | B22: 15046 | C22: 147 | D22: 7.22 | E22: 0.012 | F22: 292 | G22: =F22*C22 -> 42924 | H22: 1.02 | I22: 1387 | J22: 22542 | K22: 3 | L22: =E22-评价标准!M22 -> 0.002 | M22: =N22-评价标准!N22 -> 0.00012491325 | N22: =G22/G21 -> 1.0201249
A23: 17 | B23: 49992 | C23: 148.8 | D23: 7.36 | E23: 0.005 | F23: 292 | G23: =F23*C23 -> 43449.6 | H23: 1.1 | I23: 458 | J23: 23000 | L23: =E23-评价标准!M23 -> 0 | M23: =N23-评价标准!N23 -> 0.012244898 | N23: =G23/G22 -> 1.0122449
A24: 18
A25: 19
A26: 20

Sheet 10
A2: Lot No. | B2: 2616 | D2: Seed No. | E2: 2596 | G2: Yield Y30 kg | H2: =G23-E4 -> 39090.161
A3: Strain | B3: 167 | D3: Seed m3 | E3: 7.3
A4: Recipe | B4: Diff | D4: Seed Y30 | E4: =42431*E3/66.5 -> 4657.8391
A5: time | B5: Air m3/h | C5: Volume | D5: pH | E5: Alcohol v/v% | F5: Cell gpl | G5: Y30 kg | H5: GM | I5: RS kg/h | J5: TFS | K5: Remark | L5: DeltaAlcohol | M5: DeltaGM | N5: AutoGM
A6: 0 | B6: 9567 | C6: 89.1 | D6: 5.65 | E6: 0.148 | F6: 59 | G6: 5257 | J6: 300 | L6: =E6-评价标准!M6 -> -0.052
A7: 1 | B7: 9115 | C7: 89.9 | D7: 4.85 | E7: 0.259 | F7: 73 | G7: 6562 | H7: 1.24 | I7: 563 | J7: =J6+I7 -> 863 | K7: 3.5 | L7: =E7-评价标准!M7 -> 0.009 | M7: =N7-评价标准!N7 -> 0.048240441 | N7: =G7/G6 -> 1.2482404
A8: 2 | B8: 10460 | C8: 92.4 | D8: 4.21 | E8: 0.243 | F8: 99 | G8: 9147 | H8: 1.39 | I8: 574 | J8: =J7+I8 -> 1437 | K8: 4 | L8: =E8-评价标准!M8 -> 0.013 | M8: =N8-评价标准!N8 -> -0.006065224 | N8: =G8/G7 -> 1.3939348
A9: 3 | B9: 12456 | C9: 93.4 | D9: 3.98 | E9: 0.195 | F9: 113 | G9: 10610 | H9: 1.16 | I9: 657 | J9: =J8+I9 -> 2094 | K9: 3.5 | L9: =E9-评价标准!M9 -> -0.005 | M9: =N9-评价标准!N9 -> -0.19005685 | N9: =G9/G8 -> 1.1599432
A10: 4 | B10: 14564 | C10: 95.9 | D10: 4.07 | E10: 0.125 | F10: 136 | G10: 13042 | H10: 1.23 | I10: 877 | J10: =J9+I10 -> 2971 | K10: 3.5 | L10: =E10-评价标准!M10 -> -0.055 | M10: =N10-评价标准!N10 -> -0.10078228 | N10: =G10/G9 -> 1.2292177
A11: 5 | B11: 16457 | C11: 98.9 | D11: 4.45 | E11: 0.105 | F11: 154 | G11: 15230 | H11: 1.17 | I11: 1132 | J11: =J10+I11 -> 4103 | K11: 4 | L11: =E11-评价标准!M11 -> -0.055 | M11: =N11-评价标准!N11 -> -0.13223432 | N11: =G11/G10 -> 1.1677657
A12: 6 | B12: 17244 | C12: 102.1 | D12: 5.02 | E12: 0.133 | F12: 180 | G12: 18378 | H12: 1.21 | I12: 1243 | J12: =J11+I12 -> 5346 | K12: 3.5 | L12: =E12-评价标准!M12 -> -0.007 | M12: =N12-评价标准!N12 -> -0.043302692 | N12: =G12/G11 -> 1.2066973
A13: 7 | B13: 19098 | C13: 105.4 | D13: 5.64 | E13: 0.112 | F13: 190 | G13: 20026 | H13: 1.09 | I13: 1267 | J13: =J12+I13 -> 6613 | K13: 3 | L13: =E13-评价标准!M13 -> -0.018 | M13: =N13-评价标准!N13 -> -0.12032757 | N13: =G13/G12 -> 1.0896724
A14: 8 | B14: 20045 | C14: 110.7 | D14: 5.99 | E14: 0.108 | F14: 207 | G14: 22915 | H14: 1.14 | I14: 1433 | J14: =J13+I14 -> 8046 | K14: 4 | L14: =E14-评价标准!M14 -> -0.012 | M14: =N14-评价标准!N14 -> -0.045737541 | N14: =G14/G13 -> 1.1442625
A15: 9 | B15: 19885 | C15: 114.7 | D15: 6.06 | E15: 0.115 | F15: 217 | G15: 24890 | H15: 1.09 | I15: 1569 | J15: =J14+I15 -> 9615 | K15: 3 | L15: =E15-评价标准!M15 -> 0.005 | M15: =N15-评价标准!N15 -> -0.083811914 | N15: =G15/G14 -> 1.0861881
A16: 10 | B16: 20018 | C16: 118.8 | D16: 6.26 | E16: 0.112 | F16: 235 | G16: 27918 | H16: 1.12 | I16: 1702 | J16: =J15+I16 -> 11317 | K16: 4 | L16: =E16-评价标准!M16 -> 0.012 | M16: =N16-评价标准!N16 -> -0.028344717 | N16: =G16/G15 -> 1.1216553
A17: 11 | B17: 19975 | C17: 123 | D17: 6.34 | E17: 0.097 | F17: 247 | G17: 30381 | H17: 1.09 | I17: 1889 | J17: =J16+I17 -> 13206 | K17: 4 | L17: =E17-评价标准!M17 -> 0.007 | M17: =N17-评价标准!N17 -> -0.041777348 | N17: =G17/G16 -> 1.0882227
A18: 12 | B18: 19764 | C18: 127.7 | D18: 6.42 | E18: 0.088 | F18: 263 | G18: 33385 | H18: 1.11 | I18: 2010 | J18: =J17+I18 -> 15216 | K18: 4 | L18: =E18-评价标准!M18 -> 0.008 | M18: =N18-评价标准!N18 -> -0.011122412 | N18: =G18/G17 -> 1.0988776
... A22: 16 | B22: 14698 | C22: 146.1 | D22: 7.37 | E22: 0.026 | F22: 296 | G22: 43246 | H22: 1.03 | I22: 1518 | J22: =J21+I22 -> 22400 | K22: 3 | L22: =E22-评价标准!M22 -> 0.016 | M22: =N22-评价标准!N22 -> -0.039831826 | N22: =G22/G21 -> 0.98016817
A23: 17 | B23: 4970 | C23: 147.8 | D23: 7.59 | E23: 0.009 | F23: 296 | G23: 43748 | H23: 1.01 | I23: 600 | J23: =J22+I23 -> 23000 | L23: =E23-评价标准!M23 -> 0.004 | M23: =N23-评价标准!N23 -> 0.01160801 | N23: =G23/G22 -> 1.011608
A24: 18
A25: 19
A26: 20

Sheet 11
A2: Lot No. | B2: 2616 | D2: Seed No. | E2: 2596 | G2: Yield Y30 kg | H2: =G23-E4 -> 39090.161
A3: Strain | B3: 167 | D3: Seed m3 | E3: 7.3
A4: Recipe | B4: Diff | D4: Seed Y30 | E4: =42431*E3/66.5 -> 4657.8391
A5: time | B5: Air m3/h | C5: Volume | D5: pH | E5: Alcohol v/v% | F5: Cell gpl | G5: Y30 kg | H5: GM | I5: RS kg/h | J5: TFS | K5: Remark | L5: DeltaAlcohol | M5: DeltaGM | N5: AutoGM
A6: 0 | E6: 0.148 | G6: 5257 | J6: 300 | L6: =E6-评价标准!M6 -> -0.052
A7: 1 | E7: 0.259 | G7: 6562 | I7: 563 | J7: =J6+I7 -> 863 | L7: =E7-评价标准!M7 -> 0.009 | M7: =N7-评价标准!N7 -> 0.048240441 | N7: =G7/G6 -> 1.2482404
A8: 2 | E8: 0.243 | G8: 9147 | I8: 574 | J8: =J7+I8 -> 1437 | L8: =E8-评价标准!M8 -> 0.013 | M8: =N8-评价标准!N8 -> -0.006065224 | N8: =G8/G7 -> 1.3939348
A9: 3 | E9: 0.195 | G9: 10610 | I9: 657 | J9: =J8+I9 -> 2094 | L9: =E9-评价标准!M9 -> -0.005 | M9: =N9-评价标准!N9 -> -0.19005685 | N9: =G9/G8 -> 1.1599432
A10: 4 | E10: 0.125 | G10: 13042 | I10: 877 | J10: =J9+I10 -> 2971 | L10: =E10-评价标准!M10 -> -0.055 | M10: =N10-评价标准!N10 -> -0.10078228 | N10: =G10/G9 -> 1.2292177
A11: 5 | E11: 0.105 | G11: 15230 | I11: 1132 | J11: =J10+I11 -> 4103 | L11: =E11-评价标准!M11 -> -0.055 | M11: =N11-评价标准!N11 -> -0.13223432 | N11: =G11/G10 -> 1.1677657
A12: 6 | E12: 0.133 | G12: 18378 | I12: 1243 | J12: =J11+I12 -> 5346 | L12: =E12-评价标准!M12 -> -0.007 | M12: =N12-评价标准!N12 -> -0.043302692 | N12: =G12/G11 -> 1.2066973
A13: 7 | E13: 0.112 | G13: 20026 | I13: 1267 | J13: =J12+I13 -> 6613 | L13: =E13-评价标准!M13 -> -0.018 | M13: =N13-评价标准!N13 -> -0.12032757 | N13: =G13/G12 -> 1.0896724
A14: 8 | E14: 0.108 | G14: 22915 | I14: 1433 | J14: =J13+I14 -> 8046 | L14: =E14-评价标准!M14 -> -0.012 | M14: =N14-评价标准!N14 -> -0.045737541 | N14: =G14/G13 -> 1.1442625
A15: 9 | E15: 0.115 | G15: 24890 | I15: 1569 | J15: =J14+I15 -> 9615 | L15: =E15-评价标准!M15 -> 0.005 | M15: =N15-评价标准!N15 -> -0.083811914 | N15: =G15/G14 -> 1.0861881
A16: 10 | E16: 0.112 | G16: 27918 | I16: 1702 | J16: =J15+I16 -> 11317 | L16: =E16-评价标准!M16 -> 0.012 | M16: =N16-评价标准!N16 -> -0.028344717 | N16: =G16/G15 -> 1.1216553
A17: 11 | E17: 0.097 | G17: 30381 | I17: 1889 | J17: =J16+I17 -> 13206 | L17: =E17-评价标准!M17 -> 0.007 | M17: =N17-评价标准!N17 -> -0.041777348 | N17: =G17/G16 -> 1.0882227
A18: 12 | E18: 0.088 | G18: 33385 | I18: 2010 | J18: =J17+I18 -> 15216 | L18: =E18-评价标准!M18 -> 0.008 | M18: =N18-评价标准!N18 -> -0.011122412 | N18: =G18/G17 -> 1.0988776
... A23: 17 | E23: 0.009 | G23: 43748 | I23: 600 | J23: =J22+I23 -> 23000 | L23: =E23-评价标准!M23 -> 0.004 | M23: =N23-评价标准!N23 -> 0.01160801 | N23: =G23/G22 -> 1.011608
A24: 18
A25: 19
A26: 20

Sheet 12
A2: Lot No. | B2: 2615 | D2: Seed No. | G2: Yield Y30 kg
A3: Strain | B3: 167 | D3: Seed m3
A4: Recipe | B4: Diff | D4: Seed Y30
A5: time | B5: Air m3/h | C5: Volume | D5: pH | E5: Alcohol v/v% | F5: Cell gpl | G5: Y30 kg | H5: GM | I5: RS kg/h | J5: TFS | K5: Remark
A6: 0 | E6: 0.13 | G6: 5405 | J6: 300
A7: 1 | E7: 0.274 | G7: 6586 | I7: 472
A8: 2 | E8: 0.238 | G8: 7678 | I8: 514
A9: 3 | E9: 0.202 | G9: 10252 | I9: 655
A10: 4 | E10: 0.128 | G10: 12591 | I10: 862
A11: 5 | E11: 0.109 | G11: 15267 | I11: 1096
A12: 6 | E12: 0.155 | G12: 17574 | I12: 1148
A13: 7 | E13: 0.155 | G13: 19678 | I13: 1256
A14: 8 | E14: 0.138 | G14: 22680 | I14: 1282
A15: 9 | E15: 0.133 | G15: 24651 | I15: 1440
A16: 10 | E16: 0.104 | G16: 26653 | I16: 1475
A17: 11 | E17: 0.091 | G17: 29088 | I17: 1636
A18: 12 | E18: 0.07 | G18: 30974 | I18: 1848
... A24: 18 | E24: 0.005 | G24: 43333 | I24: 366
A25: 19
A26: 20

Sheet 13
A2: Lot No. | B2: 2617 | D2: Seed No. | G2: Yield Y30 kg
A3: Strain | B3: 167 | D3: Seed m3
A4: Recipe | B4: Diff | D4: Seed Y30
A5: time | B5: Air m3/h | C5: Volume | D5: pH | E5: Alcohol v/v% | F5: Cell gpl | G5: Y30 kg | H5: GM | I5: RS kg/h | J5: TFS | K5: Remark
A6: 0 | E6: 0.128 | G6: 5116 | J6: 300
A7: 1 | E7: 0.211 | G7: 6408 | I7: 618
A8: 2 | E8: 0.177 | G8: 8876 | I8: 531
A9: 3 | E9: 0.143 | G9: 10916 | I9: 691
A10: 4 | E10: 0.137 | G10: 12377 | I10: 916
A11: 5 | E11: 0.129 | G11: 14963 | I11: 1091
A12: 6 | E12: 0.123 | G12: 17688 | I12: 1141
A13: 7 | E13: 0.11 | G13: 19855 | I13: 1298
A14: 8 | E14: 0.096 | G14: 22974 | I14: 1403
A15: 9 | E15: 0.09 | G15: 26080 | I15: 1539
A16: 10 | E16: 0.084 | G16: 29289 | I16: 1833
A17: 11 | E17: 0.141 | G17: 31546 | I17: 1679
A18: 12 | E18: 0.11 | G18: 34047 | I18: 1711
... A23: 17 | E23: 0.011 | G23: 40590 | I23: 904
A24: 18
A25: 19
A26: 20

Sheet 14
A2: Lot No. | B2: 2621 | D2: Seed No. | G2: Yield Y30 kg
A3: Strain | B3: 167 | D3: Seed m3
A4: Recipe | B4: Diff | D4: Seed Y30
A5: time | B5: Air m3/h | C5: Volume | D5: pH | E5: Alcohol v/v% | F5: Cell gpl | G5: Y30 kg | H5: GM | I5: RS kg/h | J5: TFS | K5: Remark
A6: 0 | E6: 0.134 | G6: 5334 | J6: 300
A7: 1 | E7: 0.224 | G7: 6335 | I7: 705
A8: 2 | E8: 0.159 | G8: 8547 | I8: 535
A9: 3 | E9: 0.159 | G9: 10925 | I9: 807
A10: 4 | E10: 0.1 | G10: 12954 | I10: 927
A11: 5 | E11: 0.081 | G11: 14385 | I11: 1230
A12: 6 | E12: 0.083 | G12: 17609 | I12: 1420
A13: 7 | E13: 0.079 | G13: 20862 | I13: 1455
A14: 8 | E14: 0.084 | G14: 22385 | I14: 1786
A15: 9 | E15: 0.156 | G15: 28536 | I15: 1630
A16: 10 | E16: 0.156 | G16: 30751 | I16: 1591
A17: 11 | E17: 0.117 | G17: 32918 | I17: 1762
A18: 12 | E18: 0.12 | G18: 35748 | I18: 1864
... A22: 16 | E22: 0.003 | G22: 44459 | I22: 1455
A23: 17
A24: 18
A25: 19
A26: 20

Sheet 15
A2: Lot No. | B2: 2622 | D2: Seed No. | G2: Yield Y30 kg
A3: Strain | B3: 167 | D3: Seed m3
A4: Recipe | B4: Diff | D4: Seed Y30
A5: time | B5: Air m3/h | C5: Volume | D5: pH | E5: Alcohol v/v% | F5: Cell gpl | G5: Y30 kg | H5: GM | I5: RS kg/h | J5: TFS | K5: Remark
A6: 0 | E6: 0.13 | G6: 5340 | J6: 300
A7: 1 | E7: 0.265 | G7: 5358 | I7: 376
A8: 2 | E8: 0.35 | G8: 6335 | I8: 528
A9: 3 | E9: 0.275 | G9: 10175 | I9: 536
A10: 4 | E10: 0.156 | G10: 11635 | I10: 599
A11: 5 | E11: 0.111 | G11: 14341 | I11: 1006
A12: 6 | E12: 0.12 | G12: 16967 | I12: 1253
A13: 7 | E13: 0.142 | G13: 19674 | I13: 1450
A14: 8 | E14: 0.123 | G14: 22687 | I14: 1484
A15: 9 | E15: 0.069 | G15: 25374 | I15: 1756
A16: 10 | E16: 0.129 | G16: 28987 | I16: 1872
A17: 11 | E17: 0.104 | G17: 32116 | I17: 1863
A18: 12 | E18: 0.078 | G18: 34641 | I18: 1814
... A23: 17 | E23: 0.002 | G23: 43737 | I23: 728
A24: 18
A25: 19
A26: 20

Sheet 16
A2: Lot No. | B2: 2624 | D2: Seed No. | G2: Yield Y30 kg
A3: Strain | B3: 167 | D3: Seed m3
A4: Recipe | B4: Diff | D4: Seed Y30
A5: time | B5: Air m3/h | C5: Volume | D5: pH | E5: Alcohol v/v% | F5: Cell gpl | G5: Y30 kg | H5: GM | I5: RS kg/h | J5: TFS | K5: Remark
A6: 0 | E6: 0.2 | G6: 5006 | J6: 300
A7: 1 | E7: 0.24 | G7: 6224 | I7: 459
A8: 2 | E8: 0.235 | G8: 8725 | I8: 538
A9: 3 | E9: 0.236 | G9: 10974 | I9: 650
A10: 4 | E10: 0.173 | G10: 12985 | I10: 858
A11: 5 | E11: 0.135 | G11: 14656 | I11: 989
A12: 6 | E12: 0.138 | G12: 17065 | I12: 1202
A13: 7 | E13: 0.102 | G13: 20266 | I13: 1245
A14: 8 | E14: 0.081 | G14: 22685 | I14: 1544
A15: 9 | E15: 0.088 | G15: 25207 | I15: 1731
A16: 10 | E16: 0.128 | G16: 28197 | I16: 1654
A17: 11 | E17: 0.144 | G17: 31374 | I17: 1703
A18: 12 | E18: 0.121 | G18: 34060 | I18: 1698
... A23: 17 | E23: 0.006 | G23: 45051 | I23: 1322
A24: 18
A25: 19
A26: 20

Sheet 17
A2: Lot No. | B2: 2629 | D2: Seed No. | G2: Yield Y30 kg
A3: Strain | B3: 167 | D3: Seed m3
A4: Recipe | B4: Diff | D4: Seed Y30
A5: time | B5: Air m3/h | C5: Volume | D5: pH | E5: Alcohol v/v% | F5: Cell gpl | G5: Y30 kg | H5: GM | I5: RS kg/h | J5: TFS | K5: Remark
A6: 0 | E6: 0.141 | G6: 5352 | J6: 300
A7: 1 | E7: 0.208 | G7: 6300 | I7: 433
A8: 2 | E8: 0.162 | G8: 7328 | I8: 534
A9: 3 | E9: 0.115 | G9: 10892 | I9: 641
A10: 4 | E10: 0.072 | G10: 12441 | I10: 913
A11: 5 | E11: 0.107 | G11: 15428 | I11: 1261
A12: 6 | E12: 0.109 | G12: 18728 | I12: 1139
A13: 7 | E13: 0.093 | G13: 21326 | I13: 1341
A14: 8 | E14: 0.081 | G14: 24320 | I14: 1513
A15: 9 | E15: 0.087 | G15: 27027 | I15: 1722
A16: 10 | E16: 0.077 | G16: 29817 | I16: 1693
A17: 11 | E17: 0.062 | G17: 33000 | I17: 1778
A18: 12 | E18: 0.043 | G18: 36272 | I18: 1927
... A23: 17 | E23: 0.006 | G23: 43872 | I23: 494
A24: 18
A25: 19
A26: 20

Sheet 18
A2: Lot No. | B2: 2625 | D2: Seed No. | G2: Yield Y30 kg
A3: Strain | B3: 167 | D3: Seed m3
A4: Recipe | B4: Diff | D4: Seed Y30
A5: time | B5: Air m3/h | C5: Volume | D5: pH | E5: Alcohol v/v% | F5: Cell gpl | G5: Y30 kg | H5: GM | I5: RS kg/h | J5: TFS | K5: Remark
A6: 0 | E6: 0.144 | G6: 5245 | J6: 300
A7: 1 | E7: 0.256 | G7: 6593 | I7: 394
A8: 2 | E8: 0.25 | G8: 8299 | I8: 514
A9: 3 | E9: 0.207 | G9: 10678 | I9: 595
A10: 4 | E10: 0.185 | G10: 12874 | I10: 864
A11: 5 | E11: 0.133 | G11: 15246 | I11: 1084
A12: 6 | E12: 0.189 | G12: 18266 | I12: 1160
A13: 7 | E13: 0.115 | G13: 20438 | I13: 1109
A14: 8 | E14: 0.14 | G14: 23908 | I14: 1320
A15: 9 | E15: 0.138 | G15: 25801 | I15: 1533
A16: 10 | E16: 0.109 | G16: 28059 | I16: 1439
A17: 11 | E17: 0.079 | G17: 30479 | I17: 1774
A18: 12 | E18: 0.07 | G18: 35769 | I18: 1941
... A24: 18 | E24: 0.005 | G24: 44254 | I24: 383
A25: 19
A26: 20

Sheet 19
A2: Lot No. | B2: 2631 | D2: Seed No. | G2: Yield Y30 kg
A3: Strain | B3: 167 | D3: Seed m3
A4: Recipe | B4: Diff | D4: Seed Y30
A5: time | B5: Air m3/h | C5: Volume | D5: pH | E5: Alcohol v/v% | F5: Cell gpl | G5: Y30 kg | H5: GM | I5: RS kg/h | J5: TFS | K5: Remark
A6: 0 | E6: 0.167 | G6: 6066 | J6: 300
A7: 1 | E7: 0.251 | G7: 7323 | I7: 438
A8: 2 | E8: 0.177 | G8: 7783 | I8: 625
A9: 3 | E9: 0.182 | G9: 11316 | I9: 823
A10: 4 | E10: 0.129 | G10: 13728 | I10: 884
A11: 5 | E11: 0.176 | G11: 16549 | I11: 1120
A12: 6 | E12: 0.133 | G12: 19232 | I12: 1123
A13: 7 | E13: 0.145 | G13: 21394 | I13: 1229
A14: 8 | E14: 0.134 | G14: 23470 | I14: 1504
A15: 9 | E15: 0.165 | G15: 26724 | I15: 1583
A16: 10 | E16: 0.079 | G16: 29791 | I16: 1741
A17: 11 | E17: 0.072 | G17: 32796 | I17: 1771
A18: 12 | E18: 0.102 | G18: 35235 | I18: 1739
... A23: 17 | E23: 0.005 | G23: 43819 | I23: 929
A24: 18
A25: 19
A26: 20

Sheet 20
A2: Lot No. | B2: 2633 | D2: Seed No. | G2: Yield Y30 kg
A3: Strain | B3: 167 | D3: Seed m3
A4: Recipe | B4: Diff | D4: Seed Y30
A5: time | B5: Air m3/h | C5: Volume | D5: pH | E5: Alcohol v/v% | F5: Cell gpl | G5: Y30 kg | H5: GM | I5: RS kg/h | J5: TFS | K5: Remark
A6: 0 | E6: 0.209 | G6: 5447 | J6: 300
A7: 1 | E7: 0.235 | G7: 6217 | I7: 532
A8: 2 | E8: 0.213 | G8: 9296 | I8: 649
A9: 3 | E9: 0.169 | G9: 11447 | I9: 729
A10: 4 | E10: 0.13 | G10: 14312 | I10: 961
A11: 5 | E11: 0.17 | G11: 16968 | I11: 1193
A12: 6 | E12: 0.175 | G12: 19496 | I12: 1142
A13: 7 | E13: 0.121 | G13: 22739 | I13: 1224
A14: 8 | E14: 0.144 | G14: 24706 | I14: 1447
A15: 9 | E15: 0.126 | G15: 26796 | I15: 1547
A16: 10 | E16: 0.089 | G16: 29113 | I16: 1571
A17: 11 | E17: 0.077 | G17: 32302 | I17: 1927
A18: 12 | E18: 0.06 | G18: 35681 | I18: 2067
... A23: 17 | E23: 0.01 | G23: 44998 | I23: 598
A24: 18
A25: 19
A26: 20

Sheet 21
A2: Lot No. | B2: 2634 | D2: Seed No. | G2: Yield Y30 kg
A3: Strain | B3: 167 | D3: Seed m3
A4: Recipe | B4: Diff | D4: Seed Y30
A5: time | B5: Air m3/h | C5: Volume | D5: pH | E5: Alcohol v/v% | F5: Cell gpl | G5: Y30 kg | H5: GM | I5: RS kg/h | J5: TFS | K5: Remark
A6: 0 | E6: 0.159 | G6: 5487 | J6: 300
A7: 1 | E7: 0.247 | G7: 6497 | I7: 426
A8: 2 | E8: 0.188 | G8: 9370 | I8: 517
A9: 3 | E9: 0.154 | G9: 11441 | I9: 653
A10: 4 | E10: 0.114 | G10: 12946 | I10: 770
A11: 5 | E11: 0.111 | G11: 15405 | I11: 1067
A12: 6 | E12: 0.109 | G12: 17782 | I12: 1074
A13: 7 | E13: 0.093 | G13: 20144 | I13: 1190
A14: 8 | E14: 0.077 | G14: 22063 | I14: 1366
A15: 9 | E15: 0.089 | G15: 24772 | I15: 1480
A16: 10 | E16: 0.076 | G16: 27939 | I16: 1667
A17: 11 | E17: 0.069 | G17: 30375 | I17: 1888
A18: 12 | E18: 0.085 | G18: 33549 | I18: 1909
... A24: 18 | E24: 0.003 | G24: 43569 | I24: 153
A25: 19
A26: 20

Sheet 22
A2: Lot No. | B2: 2638 | D2: Seed No. | G2: Yield Y30 kg
A3: Strain | B3: 167 | D3: Seed m3
A4: Recipe | B4: Diff | D4: Seed Y30
A5: time | B5: Air m3/h | C5: Volume | D5: pH | E5: Alcohol v/v% | F5: Cell gpl | G5: Y30 kg | H5: GM | I5: RS kg/h | J5: TFS | K5: Remark
A6: 0 | E6: 0.165 | G6: 5327 | J6: 300
A7: 1 | E7: 0.267 | G7: 5524 | I7: 238
A8: 2 | E8: 0.233 | G8: 6570 | I8: 426
A9: 3 | E9: 0.201 | G9: 9589 | I9: 600
A10: 4 | E10: 0.145 | G10: 11483 | I10: 706
A11: 5 | E11: 0.106 | G11: 13914 | I11: 926
A12: 6 | E12: 0.116 | G12: 16265 | I12: 1207
A13: 7 | E13: 0.095 | G13: 19712 | I13: 1336
A14: 8 | E14: 0.053 | G14: 22411 | I14: 1532
A15: 9 | E15: 0.116 | G15: 25348 | I15: 1730
A16: 10 | E16: 0.141 | G16: 28440 | I16: 1320
A17: 11 | E17: 0.087 | G17: 30353 | I17: 1441
A18: 12 | E18: 0.083 | G18: 31802 | I18: 1548
... A24: 18 | E24: 0.009 | G24: 44666 | I24: 795
A25: 19
A26: 20

Sheet 23
A2: Lot No. | B2: 2639 | D2: Seed No. | G2: Yield Y30 kg
A3: Strain | B3: 167 | D3: Seed m3
A4: Recipe | B4: Diff | D4: Seed Y30
